Workbook
Name Cloth_B_Calc_Base_Stat_List: FRS!$AH$31:$AM$82
Name Cloth_B_Calc_Name_List: FRS!$AH$31:$AH$82
Name Cloth_D_Calc_Base_Stat_List: FRS!$R$31:$W$84
Name Cloth_D_Calc_Name_List: FRS!$R$31:$R$84
Name Cloth_T_Calc_Base_Stat_List: FRS!$Z$31:$AE$82
Name Cloth_T_Calc_Name_List: FRS!$Z$31:$Z$82
Name FRS_Item_Get_Get_List_V: FRS!$AV$93:$AV$119
Name FRS_Item_Get_Give_List_H: FRS!$AW$92:$BW$92
Name FRS_Item_Give_Get_List_V: FRS!$AV$136:$AV$162
Name FRS_Item_Give_Give_List_H: FRS!$AW$135:$BW$135
Name FRS_Trading_List_Get_Full: FRS!$AV$92:$BW$119
Name FRS_Trading_List_Give_Full: FRS!$AV$135:$BW$162
Name Rarity_List_Universal: FRS!$B$18:$B$21
Name Trinkets_Calc_Base_Stat_List: FRS!$B$31:$G$61
Name Trinkets_Calc_Name_List: FRS!$B$31:$B$61
Name Weapon_Calc_Base_Stat_List: FRS!$J$31:$O$74
Name Weapon_Calc_Name_List: FRS!$J$31:$J$74
Name Base_Stat_CD: 'Cloths Dresses'!$W$38
Name Cloth_B_Calc_Base_Stat_List: FRS!$AH$31:$AM$82
Name Cloth_B_Calc_Name_List: FRS!$AH$31:$AH$82
Name Cloth_D_Calc_Base_Stat_A: 'Cloths Dresses'!$W$10
Name Cloth_D_Calc_Base_Stat_F: 'Cloths Dresses'!$Y$10
Name Cloth_D_Calc_Base_Stat_I: 'Cloths Dresses'!$X$10
Name Cloth_D_Calc_Base_Stat_List: FRS!$R$31:$W$84
Name Cloth_D_Calc_Base_Stat_U: 'Cloths Dresses'!$Z$10
Name Cloth_D_Calc_Base_Stat_W: 'Cloths Dresses'!$V$10
Name Cloth_D_Calc_Level: 'Cloths Dresses'!$W$4
Name Cloth_D_Calc_Name: 'Cloths Dresses'!$U$4
Name Cloth_D_Calc_Name_List: FRS!$R$31:$R$84
Name Cloth_D_Calc_Progress_Num_A: 'Cloths Dresses'!$W$9
Name Cloth_D_Calc_Progress_Num_F: 'Cloths Dresses'!$Y$9
Name Cloth_D_Calc_Progress_Num_I: 'Cloths Dresses'!$X$9
Name Cloth_D_Calc_Progress_Num_U: 'Cloths Dresses'!$Z$9
Name Cloth_D_Calc_Progress_Num_W: 'Cloths Dresses'!$V$9
Name Cloth_D_Calc_Rarity: 'Cloths Dresses'!$V$4
Name Cloth_D_Calc_Tier_A: 'Cloths Dresses'!$W$8
Name Cloth_D_Calc_Tier_F: 'Cloths Dresses'!$Y$8
Name Cloth_D_Calc_Tier_I: 'Cloths Dresses'!$X$8
Name Cloth_D_Calc_Tier_U: 'Cloths Dresses'!$Z$8
Name Cloth_D_Calc_Tier_W: 'Cloths Dresses'!$V$8
Name Cloth_T_Calc_Base_Stat_List: FRS!$Z$31:$AE$82
Name Cloth_T_Calc_Name_List: FRS!$Z$31:$Z$82
Name FRS_Item_Get_Get_List_V: FRS!$AV$93:$AV$119
Name FRS_Item_Get_Give_List_H: FRS!$AW$92:$BW$92
Name FRS_Item_Give_Get_List_V: FRS!$AV$136:$AV$162
Name FRS_Item_Give_Give_List_H: FRS!$AW$135:$BW$135
Name FRS_Trading_List_Get_Full: FRS!$AV$92:$BW$119
Name FRS_Trading_List_Give_Full: FRS!$AV$135:$BW$162
Name Item_Level_CD: 'Cloths Dresses'!$U$38
Name Prog_Number_CD: 'Cloths Dresses'!$V$38
Name Rarity_List_Universal: FRS!$B$18:$B$21
Name Trinkets_Calc_Base_Stat_List: FRS!$B$31:$G$61
Name Trinkets_Calc_Name_List: FRS!$B$31:$B$61
Name Weapon_Calc_Base_Stat_List: FRS!$J$31:$O$74
Name Weapon_Calc_Name_List: FRS!$J$31:$J$74
Name Cloth_B_Calc_Base_Stat_List: FRS!$AH$31:$AM$82
Name Cloth_B_Calc_Name_List: FRS!$AH$31:$AH$82
Name Cloth_B_Calc_Progress_Num_A: Combos!$AT$29
Name Cloth_B_Calc_Progress_Num_F: Combos!$AV$29
Name Cloth_B_Calc_Progress_Num_I: Combos!$AU$29

Sheet 有
A1: 名字 | B1: 中名 | C1: 手填 等级 | D1: 获取 | E1: 稀有度(中文) | F1: 技能描述翻译 | G1: 初始 | H1: 游戏内截图翻译（WA近战先手I远程先 | I1: 最佳 | J1: 最差 | K1: 技 | L1: 装备 | M1: 装备备注 | N1: 列1 | O1: 列3 | P1: W | Q1: A | R1: I | S1: F | T1: U | U1: 总属 | V1: 列5 | W1: 等级 推理 | X1: 列7 | Y1: W 意志(裸装) | Z1: A 敏捷(裸装) | AA1: I 智力(裸装) | AB1: F 血量(裸装) | AC1: U 免伤(裸装) | AD1: 列1222 | AE1: W 意志 | AF1: A 敏捷 | AG1: I 智力 | AH1: F 血量 | AI1: U 免伤 | AJ1: 列52 | AL1: 角色 (Name) | AM1: 最佳武器 (Weapon) | AN1: 最佳衣服 (Dress/Top & Bottom) | AO1: 最佳饰品 (Trinket) | AP1: 核心加成
A2: Kim | B2: =IFERROR(VLOOKUP($A2,全人物技能说明!$A$1:$O$99,2,FALSE),"") -> 金 | C2: 36 | D2: =IFERROR(VLOOKUP($A2,全人物技能说明!$A$1:$O$99,3,FALSE),"") -> 2箱子 | E2: =IFERROR(VLOOKUP($A2,全人物技能说明!$A$1:$O$99,4,FALSE),"") -> 稀有 | F2: =IFERROR(VLOOKUP($A2,全人物技能说明!$A$1:$O$99,7,FALSE),"") -> X4或X2武器7次，远X4八次。喷火8次。X4近锋利砍刀单次伤最高，穿甲 | G2: =IFERROR(VLOOKUP($A2,全人物技能说明!$A$1:$O$99,8,FALSE),"") -> 阅读忧郁杰作，使最多 4 名敌人眩晕 2 回合。 | H2: 朗读令人沮丧的名著，使最多 4 名敌人眩晕 2 回合。 | I2: =IFERROR(VLOOKUP($A2,全人物技能说明!$A$1:$O$99,14,FALSE),"") -> I, F, U | J2: =IFERROR(VLOOKUP($A2,全人物技能说明!$A$1:$O$99,15,FALSE),"") -> W | L2: A | M2: =IFERROR(IF(VLOOKUP($A2,全人物技能说明!$A$1:$O$99,7,FALSE)<>"",VLOOKUP($A2,全人物技能说明!$A$1:$O$99,7,FALSE),""),"") -> X4或X2武器7次，远X4八次。喷火8次。X4近锋利砍刀单次伤最高，穿甲 | O2: I | P2: =RANK(Y2,Y:Y) -> 3 | Q2: =RANK(Z2,Z:Z) -> 1 | R2: =RANK(AA2,AA:AA) -> 2 | S2: =RANK(AB2,AB:AB) -> 1 | T2: =RANK(AC2,AC:AC) -> 1 | U2: =Y2+Z2+AA2+AB2+AC2 -> 1713 | W2: =C2 -> 36 | X2: 0 | Y2: =IFERROR(VALUE(LEFT(AE2,FIND("(",AE2)-1))+($W2-1)*VALUE(MID(AE2,FIND("+",AE2)+1,FIND(")",AE2)-FIND("+",AE2)-1)),"") -> 254 | Z2: =IFERROR(VALUE(LEFT(AF2,FIND("(",AF2)-1))+($W2-1)*VALUE(MID(AF2,FIND("+",AF2)+1,FIND(")",AF2)-FIND("+",AF2)-1)),"") -> 334 | AA2: =IFERROR(VALUE(LEFT(AG2,FIND("(",AG2)-1))+($W2-1)*VALUE(MID(AG2,FIND("+",AG2)+1,FIND(")",AG2)-FIND("+",AG2)-1)),"") -> 375 | AB2: =IFERROR(VALUE(LEFT(AH2,FIND("(",AH2)-1))+($W2-1)*VALUE(MID(AH2,FIND("+",AH2)+1,FIND(")",AH2)-FIND("+",AH2)-1)),"") -> 375 | AC2: =IFERROR(VALUE(LEFT(AI2,FIND("(",AI2)-1))+($W2-1)*VALUE(MID(AI2,FIND("+",AI2)+1,FIND(")",AI2)-FIND("+",AI2)-1)),"") -> 375 | AE2: =IFERROR(VLOOKUP($A2,全人物技能说明!$A$1:$O$99,9,FALSE),"") -> 44(+6) | AF2: =IFERROR(VLOOKUP($A2,全人物技能说明!$A$1:$O$99,10,FALSE),"") -> 54(+8) | AG2: =IFERROR(VLOOKUP($A2,全人物技能说明!$A$1:$O$99,11,FALSE),"") -> 60(+9) | AH2: =IFERROR(VLOOKUP($A2,全人物技能说明!$A$1:$O$99,12,FALSE),"") -> 60(+9) | AI2: =IFERROR(VLOOKUP($A2,全人物技能说明!$A$1:$O$99,13,FALSE),"") -> 60(+9) | AL2: 意志组 (Olivia, Allura, Emily, Diana, Karin, Martina, Devi, Samantha, Lane, Trixie) | AM2: 特种冲锋枪 (Special SMG) | AN2: 陆军上校 (Army Colonel) & 陆军底部 (Army Bottom) | AO2: 染发剂 (Hair Dye) | AP2: W (意志)
A3: XX | B3: =IFERROR(VLOOKUP($A3,全人物技能说明!$A$1:$O$99,2,FALSE),"") -> XX | C3: 34 | D3: =IFERROR(VLOOKUP($A3,全人物技能说明!$A$1:$O$99,3,FALSE),"") -> 1剧情 | E3: =IFERROR(VLOOKUP($A3,全人物技能说明!$A$1:$O$99,4,FALSE),"") -> 普通 | F3: =IFERROR(VLOOKUP($A3,全人物技能说明!$A$1:$O$99,7,FALSE),"") -> X4武器6次攻击放技能，X2会更快 | G3: =IFERROR(VLOOKUP($A3,全人物技能说明!$A$1:$O$99,8,FALSE),"") -> 魅惑一名敌人，使其眩晕 2 回合，并使其受到的伤害提升 50%。 | H3: 魅惑一名敌人，使其眩晕 2 回合并增加其受到伤害 30%。 | I3: =IFERROR(VLOOKUP($A3,全人物技能说明!$A$1:$O$99,14,FALSE),"") -> A | J3: =IFERROR(VLOOKUP($A3,全人物技能说明!$A$1:$O$99,15,FALSE),"") -> W, I | L3: A | M3: =IFERROR(IF(VLOOKUP($A3,全人物技能说明!$A$1:$O$99,7,FALSE)<>"",VLOOKUP($A3,全人物技能说明!$A$1:$O$99,7,FALSE),""),"") -> X4武器6次攻击放技能，X2会更快 | O3: A | P3: =RANK(Y3,Y:Y) -> 11 | Q3: =RANK(Z3,Z:Z) -> 2 | R3: =RANK(AA3,AA:AA) -> 9 | S3: =RANK(AB3,AB:AB) -> 3 | T3: =RANK(AC3,AC:AC) -> 6 | U3: =Y3+Z3+AA3+AB3+AC3 -> 1165 | W3: =C3 -> 34 | X3: 0 | Y3: =IFERROR(VALUE(LEFT(AE3,FIND("(",AE3)-1))+($W3-1)*VALUE(MID(AE3,FIND("+",AE3)+1,FIND(")",AE3)-FIND("+",AE3)-1)),"") -> 203 | Z3: =IFERROR(VALUE(LEFT(AF3,FIND("(",AF3)-1))+($W3-1)*VALUE(MID(AF3,FIND("+",AF3)+1,FIND(")",AF3)-FIND("+",AF3)-1)),"") -> 279 | AA3: =IFERROR(VALUE(LEFT(AG3,FIND("(",AG3)-1))+($W3-1)*VALUE(MID(AG3,FIND("+",AG3)+1,FIND(")",AG3)-FIND("+",AG3)-1)),"") -> 203 | AB3: =IFERROR(VALUE(LEFT(AH3,FIND("(",AH3)-1))+($W3-1)*VALUE(MID(AH3,FIND("+",AH3)+1,FIND(")",AH3)-FIND("+",AH3)-1)),"") -> 240 | AC3: =IFERROR(VALUE(LEFT(AI3,FIND("(",AI3)-1))+($W3-1)*VALUE(MID(AI3,FIND("+",AI3)+1,FIND(")",AI3)-FIND("+",AI3)-1)),"") -> 240 | AE3: =IFERROR(VLOOKUP($A3,全人物技能说明!$A$1:$O$99,9,FALSE),"") -> 38(+5) | AF3: =IFERROR(VLOOKUP($A3,全人物技能说明!$A$1:$O$99,10,FALSE),"") -> 48(+7) | AG3: =IFERROR(VLOOKUP($A3,全人物技能说明!$A$1:$O$99,11,FALSE),"") -> 38(+5) | AH3: =IFERROR(VLOOKUP($A3,全人物技能说明!$A$1:$O$99,12,FALSE),"") -> 42(+6) | AI3: =IFERROR(VLOOKUP($A3,全人物技能说明!$A$1:$O$99,13,FALSE),"") -> 42(+6)
A4: TRIXIE | B4: =IFERROR(VLOOKUP($A4,全人物技能说明!$A$1:$O$99,2,FALSE),"") -> 翠克希 | C4: 33 | D4: =IFERROR(VLOOKUP($A4,全人物技能说明!$A$1:$O$99,3,FALSE),"") -> 2剧情 | E4: =IFERROR(VLOOKUP($A4,全人物技能说明!$A$1:$O$99,4,FALSE),"") -> 稀有 | F4: =IFERROR(VLOOKUP($A4,全人物技能说明!$A$1:$O$99,7,FALSE),"") -> 0 | G4: =IFERROR(VLOOKUP($A4,全人物技能说明!$A$1:$O$99,8,FALSE),"") -> 指挥 2 名队友瞬间攻击一名敌人。 | H4: 命令 2 名盟友立即攻击一名敌人。 | I4: =IFERROR(VLOOKUP($A4,全人物技能说明!$A$1:$O$99,14,FALSE),"") -> W | J4: =IFERROR(VLOOKUP($A4,全人物技能说明!$A$1:$O$99,15,FALSE),"") -> A, F | L4: W | M4: =IFERROR(IF(VLOOKUP($A4,全人物技能说明!$A$1:$O$99,7,FALSE)<>"",VLOOKUP($A4,全人物技能说明!$A$1:$O$99,7,FALSE),""),"") | O4: 广播 | P4: =RANK(Y4,Y:Y) -> 2 | Q4: =RANK(Z4,Z:Z) -> 13 | R4: =RANK(AA4,AA:AA) -> 6 | S4: =RANK(AB4,AB:AB) -> 12 | T4: =RANK(AC4,AC:AC) -> 7 | U4: =Y4+Z4+AA4+AB4+AC4 -> 1136 | W4: =C4 -> 33 | Y4: =IFERROR(VALUE(LEFT(AE4,FIND("(",AE4)-1))+($W4-1)*VALUE(MID(AE4,FIND("+",AE4)+1,FIND(")",AE4)-FIND("+",AE4)-1)),"") -> 272 | Z4: =IFERROR(VALUE(LEFT(AF4,FIND("(",AF4)-1))+($W4-1)*VALUE(MID(AF4,FIND("+",AF4)+1,FIND(")",AF4)-FIND("+",AF4)-1)),"") -> 198 | AA4: =IFERROR(VALUE(LEFT(AG4,FIND("(",AG4)-1))+($W4-1)*VALUE(MID(AG4,FIND("+",AG4)+1,FIND(")",AG4)-FIND("+",AG4)-1)),"") -> 234 | AB4: =IFERROR(VALUE(LEFT(AH4,FIND("(",AH4)-1))+($W4-1)*VALUE(MID(AH4,FIND("+",AH4)+1,FIND(")",AH4)-FIND("+",AH4)-1)),"") -> 198 | AC4: =IFERROR(VALUE(LEFT(AI4,FIND("(",AI4)-1))+($W4-1)*VALUE(MID(AI4,FIND("+",AI4)+1,FIND(")",AI4)-FIND("+",AI4)-1)),"") -> 234 | AE4: =IFERROR(VLOOKUP($A4,全人物技能说明!$A$1:$O$99,9,FALSE),"") -> 48(+7) | AF4: =IFERROR(VLOOKUP($A4,全人物技能说明!$A$1:$O$99,10,FALSE),"") -> 38(+5) | AG4: =IFERROR(VLOOKUP($A4,全人物技能说明!$A$1:$O$99,11,FALSE),"") -> 42(+6) | AH4: =IFERROR(VLOOKUP($A4,全人物技能说明!$A$1:$O$99,12,FALSE),"") -> 38(+5) | AI4: =IFERROR(VLOOKUP($A4,全人物技能说明!$A$1:$O$99,13,FALSE),"") -> 42(+6) | AM4: W:4, F:4 | AN4: W:5, F:4 | AO4: W:5, A:3 | AP4: 远程高伤
A5: Sophie | B5: =IFERROR(VLOOKUP($A5,全人物技能说明!$A$1:$O$99,2,FALSE),"") -> 苏菲 | C5: 33 | D5: =IFERROR(VLOOKUP($A5,全人物技能说明!$A$1:$O$99,3,FALSE),"") -> 3剧情 | E5: =IFERROR(VLOOKUP($A5,全人物技能说明!$A$1:$O$99,4,FALSE),"") -> 史诗 | F5: =IFERROR(VLOOKUP($A5,全人物技能说明!$A$1:$O$99,7,FALSE),"") -> 0 | G5: =IFERROR(VLOOKUP($A5,全人物技能说明!$A$1:$O$99,8,FALSE),"") -> 向最多 2 名血量最低的队友递出药剂，回复 [20% INT] 生命值，并在 2 回合内提升其 20% 伤害。 | H5: 向 2 名生命值最低的盟友治疗 [20% 智力] 生命值并提升其 20% 伤害，持续 2 回合。 | I5: =IFERROR(VLOOKUP($A5,全人物技能说明!$A$1:$O$99,14,FALSE),"") -> I, U | J5: =IFERROR(VLOOKUP($A5,全人物技能说明!$A$1:$O$99,15,FALSE),"") -> A | K5: I | L5: I | M5: =IFERROR(IF(VLOOKUP($A5,全人物技能说明!$A$1:$O$99,7,FALSE)<>"",VLOOKUP($A5,全人物技能说明!$A$1:$O$99,7,FALSE),""),"") | O5: 金库 | P5: =RANK(Y5,Y:Y) -> 6 | Q5: =RANK(Z5,Z:Z) -> 18 | R5: =RANK(AA5,AA:AA) -> 3 | S5: =RANK(AB5,AB:AB) -> 12 | T5: =RANK(AC5,AC:AC) -> 2 | U5: =Y5+Z5+AA5+AB5+AC5 -> 1136 | W5: =C5 -> 33 | Y5: =IFERROR(VALUE(LEFT(AE5,FIND("(",AE5)-1))+($W5-1)*VALUE(MID(AE5,FIND("+",AE5)+1,FIND(")",AE5)-FIND("+",AE5)-1)),"") -> 234 | Z5: =IFERROR(VALUE(LEFT(AF5,FIND("(",AF5)-1))+($W5-1)*VALUE(MID(AF5,FIND("+",AF5)+1,FIND(")",AF5)-FIND("+",AF5)-1)),"") -> 160 | AA5: =IFERROR(VALUE(LEFT(AG5,FIND("(",AG5)-1))+($W5-1)*VALUE(MID(AG5,FIND("+",AG5)+1,FIND(")",AG5)-FIND("+",AG5)-1)),"") -> 272 | AB5: =IFERROR(VALUE(LEFT(AH5,FIND("(",AH5)-1))+($W5-1)*VALUE(MID(AH5,FIND("+",AH5)+1,FIND(")",AH5)-FIND("+",AH5)-1)),"") -> 198 | AC5: =IFERROR(VALUE(LEFT(AI5,FIND("(",AI5)-1))+($W5-1)*VALUE(MID(AI5,FIND("+",AI5)+1,FIND(")",AI5)-FIND("+",AI5)-1)),"") -> 272 | AE5: =IFERROR(VLOOKUP($A5,全人物技能说明!$A$1:$O$99,9,FALSE),"") -> 42(+6) | AF5: =IFERROR(VLOOKUP($A5,全人物技能说明!$A$1:$O$99,10,FALSE),"") -> 32(+4) | AG5: =IFERROR(VLOOKUP($A5,全人物技能说明!$A$1:$O$99,11,FALSE),"") -> 48(+7) | AH5: =IFERROR(VLOOKUP($A5,全人物技能说明!$A$1:$O$99,12,FALSE),"") -> 38(+5) | AI5: =IFERROR(VLOOKUP($A5,全人物技能说明!$A$1:$O$99,13,FALSE),"") -> 48(+7) | AL5: 敏捷组 (PAIN, Chelsea, Gaia, Kiara, Amelia, Jane, Sonia, XX, Cloe, Tess) | AM5: 刺客匕首 (Assassin's Dagger) | AN5: 野蛮人上衣 (Barbarian Top) & 野蛮人裙 (Barbarian Skirt) | AO5: 糖弹 (Sugar Bomb) | AP5: A (敏捷)
A6: ASHLEY | B6: =IFERROR(VLOOKUP($A6,全人物技能说明!$A$1:$O$99,2,FALSE),"") -> 艾希莉 | C6: 33 | D6: =IFERROR(VLOOKUP($A6,全人物技能说明!$A$1:$O$99,3,FALSE),"") -> 5箱子 | E6: =IFERROR(VLOOKUP($A6,全人物技能说明!$A$1:$O$99,4,FALSE),"") -> 传说 | F6: =IFERROR(VLOOKUP($A6,全人物技能说明!$A$1:$O$99,7,FALSE),"") -> 无论是近战还是远程攻击，都需要 4 次攻击 | G6: =IFERROR(VLOOKUP($A6,全人物技能说明!$A$1:$O$99,8,FALSE),"") -> 使下 2 次攻击的伤害提升 200%。战斗开始时即就绪。 | H6: 增加接下来3次攻击伤害30% | I6: =IFERROR(VLOOKUP($A6,全人物技能说明!$A$1:$O$99,14,FALSE),"") -> A, U | J6: =IFERROR(VLOOKUP($A6,全人物技能说明!$A$1:$O$99,15,FALSE),"") -> I | L6: A | M6: =IFERROR(IF(VLOOKUP($A6,全人物技能说明!$A$1:$O$99,7,FALSE)<>"",VLOOKUP($A6,全人物技能说明!$A$1:$O$99,7,FALSE),""),"") -> 无论是近战还是远程攻击，都需要 4 次攻击 | O6: 矿石 | P6: =RANK(Y6,Y:Y) -> 12 | Q6: =RANK(Z6,Z:Z) -> 4 | R6: =RANK(AA6,AA:AA) -> 21 | S6: =RANK(AB6,AB:AB) -> 4 | T6: =RANK(AC6,AC:AC) -> 2 | U6: =Y6+Z6+AA6+AB6+AC6 -> 1136 | W6: =C6 -> 33 | Y6: =IFERROR(VALUE(LEFT(AE6,FIND("(",AE6)-1))+($W6-1)*VALUE(MID(AE6,FIND("+",AE6)+1,FIND(")",AE6)-FIND("+",AE6)-1)),"") -> 198 | Z6: =IFERROR(VALUE(LEFT(AF6,FIND("(",AF6)-1))+($W6-1)*VALUE(MID(AF6,FIND("+",AF6)+1,FIND(")",AF6)-FIND("+",AF6)-1)),"") -> 272 | AA6: =IFERROR(VALUE(LEFT(AG6,FIND("(",AG6)-1))+($W6-1)*VALUE(MID(AG6,FIND("+",AG6)+1,FIND(")",AG6)-FIND("+",AG6)-1)),"") -> 160 | AB6: =IFERROR(VALUE(LEFT(AH6,FIND("(",AH6)-1))+($W6-1)*VALUE(MID(AH6,FIND("+",AH6)+1,FIND(")",AH6)-FIND("+",AH6)-1)),"") -> 234 | AC6: =IFERROR(VALUE(LEFT(AI6,FIND("(",AI6)-1))+($W6-1)*VALUE(MID(AI6,FIND("+",AI6)+1,FIND(")",AI6)-FIND("+",AI6)-1)),"") -> 272 | AE6: =IFERROR(VLOOKUP($A6,全人物技能说明!$A$1:$O$99,9,FALSE),"") -> 38(+5) | AF6: =IFERROR(VLOOKUP($A6,全人物技能说明!$A$1:$O$99,10,FALSE),"") -> 48(+7) | AG6: =IFERROR(VLOOKUP($A6,全人物技能说明!$A$1:$O$99,11,FALSE),"") -> 32(+4) | AH6: =IFERROR(VLOOKUP($A6,全人物技能说明!$A$1:$O$99,12,FALSE),"") -> 42(+6) | AI6: =IFERROR(VLOOKUP($A6,全人物技能说明!$A$1:$O$99,13,FALSE),"") -> 48(+7)
A7: ANDREA | B7: =IFERROR(VLOOKUP($A7,全人物技能说明!$A$1:$O$99,2,FALSE),"") -> 安德烈亚 | C7: 32 | D7: =IFERROR(VLOOKUP($A7,全人物技能说明!$A$1:$O$99,3,FALSE),"") -> 1剧情 | E7: =IFERROR(VLOOKUP($A7,全人物技能说明!$A$1:$O$99,4,FALSE),"") -> 稀有 | F7: =IFERROR(VLOOKUP($A7,全人物技能说明!$A$1:$O$99,8,FALSE),"") -> 为 2 名血量最低的队友回复 10% 最大生命值 + [15% INT]。 | G7: =IFERROR(VLOOKUP($A7,全人物技能说明!$A$1:$O$99,8,FALSE),"") -> 为 2 名血量最低的队友回复 10% 最大生命值 + [15% INT]。 | H7: 治疗 2 名生命值最低的盟友，恢复其最大生命值的 10% + [15% 智力]。 | I7: =IFERROR(VLOOKUP($A7,全人物技能说明!$A$1:$O$99,14,FALSE),"") -> I | J7: =IFERROR(VLOOKUP($A7,全人物技能说明!$A$1:$O$99,15,FALSE),"") -> W, F | K7: I | L7: I | M7: =IFERROR(IF(VLOOKUP($A7,全人物技能说明!$A$1:$O$99,7,FALSE)<>"",VLOOKUP($A7,全人物技能说明!$A$1:$O$99,7,FALSE),""),"") -> 高电压电击枪（I 类武器伤害最高） | O7: 金库 | P7: =RANK(Y7,Y:Y) -> 13 | Q7: =RANK(Z7,Z:Z) -> 9 | R7: =RANK(AA7,AA:AA) -> 4 | S7: =RANK(AB7,AB:AB) -> 14 | T7: =RANK(AC7,AC:AC) -> 8 | U7: =Y7+Z7+AA7+AB7+AC7 -> 1107 | W7: =C7 -> 32 | X7: 0 | Y7: =IFERROR(VALUE(LEFT(AE7,FIND("(",AE7)-1))+($W7-1)*VALUE(MID(AE7,FIND("+",AE7)+1,FIND(")",AE7)-FIND("+",AE7)-1)),"") -> 193 | Z7: =IFERROR(VALUE(LEFT(AF7,FIND("(",AF7)-1))+($W7-1)*VALUE(MID(AF7,FIND("+",AF7)+1,FIND(")",AF7)-FIND("+",AF7)-1)),"") -> 228 | AA7: =IFERROR(VALUE(LEFT(AG7,FIND("(",AG7)-1))+($W7-1)*VALUE(MID(AG7,FIND("+",AG7)+1,FIND(")",AG7)-FIND("+",AG7)-1)),"") -> 265 | AB7: =IFERROR(VALUE(LEFT(AH7,FIND("(",AH7)-1))+($W7-1)*VALUE(MID(AH7,FIND("+",AH7)+1,FIND(")",AH7)-FIND("+",AH7)-1)),"") -> 193 | AC7: =IFERROR(VALUE(LEFT(AI7,FIND("(",AI7)-1))+($W7-1)*VALUE(MID(AI7,FIND("+",AI7)+1,FIND(")",AI7)-FIND("+",AI7)-1)),"") -> 228 | AE7: =IFERROR(VLOOKUP($A7,全人物技能说明!$A$1:$O$99,9,FALSE),"") -> 38(+5) | AF7: =IFERROR(VLOOKUP($A7,全人物技能说明!$A$1:$O$99,10,FALSE),"") -> 42(+6) | AG7: =IFERROR(VLOOKUP($A7,全人物技能说明!$A$1:$O$99,11,FALSE),"") -> 48(+7) | AH7: =IFERROR(VLOOKUP($A7,全人物技能说明!$A$1:$O$99,12,FALSE),"") -> 38(+5) | AI7: =IFERROR(VLOOKUP($A7,全人物技能说明!$A$1:$O$99,13,FALSE),"") -> 42(+6) | AM7: A:5, F:4 | AN7: A:5, F:5 | AO7: A:5, I:4 | AP7: 近战/暴击
A8: LADY JUDITH | B8: =IFERROR(VLOOKUP($A8,全人物技能说明!$A$1:$O$99,2,FALSE),"") -> 朱迪丝 | C8: 31 | D8: =IFERROR(VLOOKUP($A8,全人物技能说明!$A$1:$O$99,3,FALSE),"") -> 4箱子 | E8: =IFERROR(VLOOKUP($A8,全人物技能说明!$A$1:$O$99,4,FALSE),"") -> 史诗 | F8: =IFERROR(VLOOKUP($A8,全人物技能说明!$A$1:$O$99,7,FALSE),"") -> 近战X4武器8次攻击，X2稍快，远程x4武器就需要9次 | G8: =IFERROR(VLOOKUP($A8,全人物技能说明!$A$1:$O$99,8,FALSE),"") -> 召唤保镖（继承 [75% HP] 和 [75% DEF]），嘲讽敌人最多 2 回合。 | H8: 击晕所有敌人1回合,并增加接下来3次攻击伤害15% | I8: =IFERROR(VLOOKUP($A8,全人物技能说明!$A$1:$O$99,14,FALSE),"") -> W, I | J8: =IFERROR(VLOOKUP($A8,全人物技能说明!$A$1:$O$99,15,FALSE),"") -> F, U | L8: W | M8: =IFERROR(IF(VLOOKUP($A8,全人物技能说明!$A$1:$O$99,7,FALSE)<>"",VLOOKUP($A8,全人物技能说明!$A$1:$O$99,7,FALSE),""),"") -> 近战X4武器8次攻击，X2稍快，远程x4武器就需要9次 | O8: I | P8: =RANK(Y8,Y:Y) -> 1 | Q8: =RANK(Z8,Z:Z) -> 5 | R8: =RANK(AA8,AA:AA) -> 1 | S8: =RANK(AB8,AB:AB) -> 5 | T8: =RANK(AC8,AC:AC) -> 9 | U8: =Y8+Z8+AA8+AB8+AC8 -> 1490 | W8: =C8 -> 31 | X8: 0 | Y8: =IFERROR(VALUE(LEFT(AE8,FIND("(",AE8)-1))+($W8-1)*VALUE(MID(AE8,FIND("+",AE8)+1,FIND(")",AE8)-FIND("+",AE8)-1)),"") -> 396 | Z8: =IFERROR(VALUE(LEFT(AF8,FIND("(",AF8)-1))+($W8-1)*VALUE(MID(AF8,FIND("+",AF8)+1,FIND(")",AF8)-FIND("+",AF8)-1)),"") -> 258 | AA8: =IFERROR(VALUE(LEFT(AG8,FIND("(",AG8)-1))+($W8-1)*VALUE(MID(AG8,FIND("+",AG8)+1,FIND(")",AG8)-FIND("+",AG8)-1)),"") -> 396 | AB8: =IFERROR(VALUE(LEFT(AH8,FIND("(",AH8)-1))+($W8-1)*VALUE(MID(AH8,FIND("+",AH8)+1,FIND(")",AH8)-FIND("+",AH8)-1)),"") -> 220 | AC8: =IFERROR(VALUE(LEFT(AI8,FIND("(",AI8)-1))+($W8-1)*VALUE(MID(AI8,FIND("+",AI8)+1,FIND(")",AI8)-FIND("+",AI8)-1)),"") -> 220 | AE8: =IFERROR(VLOOKUP($A8,全人物技能说明!$A$1:$O$99,9,FALSE),"") -> 66(+11) | AF8: =IFERROR(VLOOKUP($A8,全人物技能说明!$A$1:$O$99,10,FALSE),"") -> 48(+7) | AG8: =IFERROR(VLOOKUP($A8,全人物技能说明!$A$1:$O$99,11,FALSE),"") -> 66(+11) | AH8: =IFERROR(VLOOKUP($A8,全人物技能说明!$A$1:$O$99,12,FALSE),"") -> 40(+6) | AI8: =IFERROR(VLOOKUP($A8,全人物技能说明!$A$1:$O$99,13,FALSE),"") -> 40(+6) | AL8: 智力组 (Eleanor, Autumn, Allura, Maria, Andrea, Sophie, Kim, Cloe, Lane) | AM8: 特斯拉枪 (Tesla Gun) | AN8: 精巧上衣 (Exquisite Top) & 霓虹灯底部 (Neon Bottom) | AO8: Lovense 礼物 (Lovense Gift) | AP8: I (智力)
A9: MARTHA | B9: =IFERROR(VLOOKUP($A9,全人物技能说明!$A$1:$O$99,2,FALSE),"") -> 玛莎 | C9: 30 | D9: =IFERROR(VLOOKUP($A9,全人物技能说明!$A$1:$O$99,3,FALSE),"") -> 1箱子 | E9: =IFERROR(VLOOKUP($A9,全人物技能说明!$A$1:$O$99,4,FALSE),"") -> 稀有 | F9: =IFERROR(VLOOKUP($A9,全人物技能说明!$A$1:$O$99,7,FALSE),"") -> 使用管武器需要5次攻击 | G9: =IFERROR(VLOOKUP($A9,全人物技能说明!$A$1:$O$99,8,FALSE),"") -> 嘲讽敌人 2 回合；减少 70% 所受到的伤害。 | H9: 对所有敌人灌输流言蜚语。将接下来6次攻击造成的伤害减少50%。 | I9: =IFERROR(VLOOKUP($A9,全人物技能说明!$A$1:$O$99,14,FALSE),"") -> U | J9: =IFERROR(VLOOKUP($A9,全人物技能说明!$A$1:$O$99,15,FALSE),"") -> W, I | L9: A | M9: =IFERROR(IF(VLOOKUP($A9,全人物技能说明!$A$1:$O$99,7,FALSE)<>"",VLOOKUP($A9,全人物技能说明!$A$1:$O$99,7,FALSE),""),"") -> 使用管武器需要5次攻击 | P9: =RANK(Y9,Y:Y) -> 17 | Q9: =RANK(Z9,Z:Z) -> 10 | R9: =RANK(AA9,AA:AA) -> 14 | S9: =RANK(AB9,AB:AB) -> 6 | T9: =RANK(AC9,AC:AC) -> 4 | U9: =Y9+Z9+AA9+AB9+AC9 -> 1049 | W9: =C9 -> 30 | X9: 1 | Y9: =IFERROR(VALUE(LEFT(AE9,FIND("(",AE9)-1))+($W9-1)*VALUE(MID(AE9,FIND("+",AE9)+1,FIND(")",AE9)-FIND("+",AE9)-1)),"") -> 183 | Z9: =IFERROR(VALUE(LEFT(AF9,FIND("(",AF9)-1))+($W9-1)*VALUE(MID(AF9,FIND("+",AF9)+1,FIND(")",AF9)-FIND("+",AF9)-1)),"") -> 216 | AA9: =IFERROR(VALUE(LEFT(AG9,FIND("(",AG9)-1))+($W9-1)*VALUE(MID(AG9,FIND("+",AG9)+1,FIND(")",AG9)-FIND("+",AG9)-1)),"") -> 183 | AB9: =IFERROR(VALUE(LEFT(AH9,FIND("(",AH9)-1))+($W9-1)*VALUE(MID(AH9,FIND("+",AH9)+1,FIND(")",AH9)-FIND("+",AH9)-1)),"") -> 216 | AC9: =IFERROR(VALUE(LEFT(AI9,FIND("(",AI9)-1))+($W9-1)*VALUE(MID(AI9,FIND("+",AI9)+1,FIND(")",AI9)-FIND("+",AI9)-1)),"") -> 251 | AE9: =IFERROR(VLOOKUP($A9,全人物技能说明!$A$1:$O$99,9,FALSE),"") -> 38(+5) | AF9: =IFERROR(VLOOKUP($A9,全人物技能说明!$A$1:$O$99,10,FALSE),"") -> 42(+6) | AG9: =IFERROR(VLOOKUP($A9,全人物技能说明!$A$1:$O$99,11,FALSE),"") -> 38(+5) | AH9: =IFERROR(VLOOKUP($A9,全人物技能说明!$A$1:$O$99,12,FALSE),"") -> 42(+6) | AI9: =IFERROR(VLOOKUP($A9,全人物技能说明!$A$1:$O$99,13,FALSE),"") -> 48(+7)
A10: JANE | B10: =IFERROR(VLOOKUP($A10,全人物技能说明!$A$1:$O$99,2,FALSE),"") -> 简 | C10: 29 | D10: =IFERROR(VLOOKUP($A10,全人物技能说明!$A$1:$O$99,3,FALSE),"") -> 1剧情 | E10: =IFERROR(VLOOKUP($A10,全人物技能说明!$A$1:$O$99,4,FALSE),"") -> 史诗 | F10: =IFERROR(VLOOKUP($A10,全人物技能说明!$A$1:$O$99,7,FALSE),"") -> 无论是近战还是远程攻击，都需要 4 次攻击 | G10: =IFERROR(VLOOKUP($A10,全人物技能说明!$A$1:$O$99,8,FALSE),"") -> 使下 2 次攻击的伤害提升 200%。战斗开始时即就绪。 | H10: 增加接下来2次攻击伤害30% | I10: =IFERROR(VLOOKUP($A10,全人物技能说明!$A$1:$O$99,14,FALSE),"") -> A, F | J10: =IFERROR(VLOOKUP($A10,全人物技能说明!$A$1:$O$99,15,FALSE),"") -> U | L10: A | M10: =IFERROR(IF(VLOOKUP($A10,全人物技能说明!$A$1:$O$99,7,FALSE)<>"",VLOOKUP($A10,全人物技能说明!$A$1:$O$99,7,FALSE),""),"") -> 无论是近战还是远程攻击，都需要 4 次攻击 | O10: F | P10: =RANK(Y10,Y:Y) -> 9 | Q10: =RANK(Z10,Z:Z) -> 6 | R10: =RANK(AA10,AA:AA) -> 17 | S10: =RANK(AB10,AB:AB) -> 2 | T10: =RANK(AC10,AC:AC) -> 23 | U10: =Y10+Z10+AA10+AB10+AC10 -> 1020 | W10: =C10 -> 29 | Y10: =IFERROR(VALUE(LEFT(AE10,FIND("(",AE10)-1))+($W10-1)*VALUE(MID(AE10,FIND("+",AE10)+1,FIND(")",AE10)-FIND("+",AE10)-1)),"") -> 210 | Z10: =IFERROR(VALUE(LEFT(AF10,FIND("(",AF10)-1))+($W10-1)*VALUE(MID(AF10,FIND("+",AF10)+1,FIND(")",AF10)-FIND("+",AF10)-1)),"") -> 244 | AA10: =IFERROR(VALUE(LEFT(AG10,FIND("(",AG10)-1))+($W10-1)*VALUE(MID(AG10,FIND("+",AG10)+1,FIND(")",AG10)-FIND("+",AG10)-1)),"") -> 178 | AB10: =IFERROR(VALUE(LEFT(AH10,FIND("(",AH10)-1))+($W10-1)*VALUE(MID(AH10,FIND("+",AH10)+1,FIND(")",AH10)-FIND("+",AH10)-1)),"") -> 244 | AC10: =IFERROR(VALUE(LEFT(AI10,FIND("(",AI10)-1))+($W10-1)*VALUE(MID(AI10,FIND("+",AI10)+1,FIND(")",AI10)-FIND("+",AI10)-1)),"") -> 144 | AE10: =IFERROR(VLOOKUP($A10,全人物技能说明!$A$1:$O$99,9,FALSE),"") -> 42(+6) | AF10: =IFERROR(VLOOKUP($A10,全人物技能说明!$A$1:$O$99,10,FALSE),"") -> 48(+7) | AG10: =IFERROR(VLOOKUP($A10,全人物技能说明!$A$1:$O$99,11,FALSE),"") -> 38(+5) | AH10: =IFERROR(VLOOKUP($A10,全人物技能说明!$A$1:$O$99,12,FALSE),"") -> 48(+7) | AI10: =IFERROR(VLOOKUP($A10,全人物技能说明!$A$1:$O$99,13,FALSE),"") -> 32(+4) | AM10: I:4, F:4 | AN10: I:5 | AO10: I:5, A:3 | AP10: 技能/治疗
A11: SONIA | B11: =IFERROR(VLOOKUP($A11,全人物技能说明!$A$1:$O$99,2,FALSE),"") -> 索尼娅 | C11: 29 | D11: =IFERROR(VLOOKUP($A11,全人物技能说明!$A$1:$O$99,3,FALSE),"") -> 3箱子 | E11: =IFERROR(VLOOKUP($A11,全人物技能说明!$A$1:$O$99,4,FALSE),"") -> 稀有 | F11: =IFERROR(VLOOKUP($A11,全人物技能说明!$A$1:$O$99,7,FALSE),"") -> 0 | G11: =IFERROR(VLOOKUP($A11,全人物技能说明!$A$1:$O$99,8,FALSE),"") -> 发动 4 连击，每次攻击造成 [75% DPS] 伤害。 | H11: 发动2次连续攻击，每次造成 [75% DPS] 伤害。 | I11: =IFERROR(VLOOKUP($A11,全人物技能说明!$A$1:$O$99,14,FALSE),"") -> A | J11: =IFERROR(VLOOKUP($A11,全人物技能说明!$A$1:$O$99,15,FALSE),"") -> I, U | K11: I | L11: I | M11: =IFERROR(IF(VLOOKUP($A11,全人物技能说明!$A$1:$O$99,7,FALSE)<>"",VLOOKUP($A11,全人物技能说明!$A$1:$O$99,7,FALSE),""),"") | O11: 矿石 | P11: =RANK(Y11,Y:Y) -> 9 | Q11: =RANK(Z11,Z:Z) -> 6 | R11: =RANK(AA11,AA:AA) -> 17 | S11: =RANK(AB11,AB:AB) -> 7 | T11: =RANK(AC11,AC:AC) -> 17 | U11: =Y11+Z11+AA11+AB11+AC11 -> 1020 | W11: =C11 -> 29 | Y11: =IFERROR(VALUE(LEFT(AE11,FIND("(",AE11)-1))+($W11-1)*VALUE(MID(AE11,FIND("+",AE11)+1,FIND(")",AE11)-FIND("+",AE11)-1)),"") -> 210 | Z11: =IFERROR(VALUE(LEFT(AF11,FIND("(",AF11)-1))+($W11-1)*VALUE(MID(AF11,FIND("+",AF11)+1,FIND(")",AF11)-FIND("+",AF11)-1)),"") -> 244 | AA11: =IFERROR(VALUE(LEFT(AG11,FIND("(",AG11)-1))+($W11-1)*VALUE(MID(AG11,FIND("+",AG11)+1,FIND(")",AG11)-FIND("+",AG11)-1)),"") -> 178 | AB11: =IFERROR(VALUE(LEFT(AH11,FIND("(",AH11)-1))+($W11-1)*VALUE(MID(AH11,FIND("+",AH11)+1,FIND(")",AH11)-FIND("+",AH11)-1)),"") -> 210 | AC11: =IFERROR(VALUE(LEFT(AI11,FIND("(",AI11)-1))+($W11-1)*VALUE(MID(AI11,FIND("+",AI11)+1,FIND(")",AI11)-FIND("+",AI11)-1)),"") -> 178 | AE11: =IFERROR(VLOOKUP($A11,全人物技能说明!$A$1:$O$99,9,FALSE),"") -> 42(+6) | AF11: =IFERROR(VLOOKUP($A11,全人物技能说明!$A$1:$O$99,10,FALSE),"") -> 48(+7) | AG11: =IFERROR(VLOOKUP($A11,全人物技能说明!$A$1:$O$99,11,FALSE),"") -> 38(+5) | AH11: =IFERROR(VLOOKUP($A11,全人物技能说明!$A$1:$O$99,12,FALSE),"") -> 42(+6) | AI11: =IFERROR(VLOOKUP($A11,全人物技能说明!$A$1:$O$99,13,FALSE),"") -> 38(+5) | AL11: 坦克组 (Beatrix, Banka, Martha, Lady Judith, Momoka, Ann, Veneza) | AM11: 巨型扳手 (Giant Wrench) | AN11: 埃莉诺·塞特 (Eleanor Set - 裙) 或 统治 (Dominance) | AO11: 手工棒棒糖 (Handmade Lollipop) | AP11: F/U (生存)
A12: Ann | B12: =IFERROR(VLOOKUP($A12,全人物技能说明!$A$1:$O$99,2,FALSE),"") -> 安 | C12: 29 | D12: =IFERROR(VLOOKUP($A12,全人物技能说明!$A$1:$O$99,3,FALSE),"") -> 3箱子 | E12: =IFERROR(VLOOKUP($A12,全人物技能说明!$A$1:$O$99,4,FALSE),"") -> 稀有 | F12: =IFERROR(VLOOKUP($A12,全人物技能说明!$A$1:$O$99,7,FALSE),"") -> X2武士刀，4次。X4匕首7次 | G12: =IFERROR(VLOOKUP($A12,全人物技能说明!$A$1:$O$99,8,FALSE),"") -> 为最多 2 名血量最低的队友提供美食，回复 [20% AGI] 生命值，并在 4 回合内提升 50% 护甲。 | H12: 为最多 2 名生命值最低的盟友治疗[20% 敏捷]并增加50%护甲，持续4 回合。 | I12: =IFERROR(VLOOKUP($A12,全人物技能说明!$A$1:$O$99,14,FALSE),"") -> U | J12: =IFERROR(VLOOKUP($A12,全人物技能说明!$A$1:$O$99,15,FALSE),"") -> W, I | K12: A | L12: A | M12: =IFERROR(IF(VLOOKUP($A12,全人物技能说明!$A$1:$O$99,7,FALSE)<>"",VLOOKUP($A12,全人物技能说明!$A$1:$O$99,7,FALSE),""),"") -> X2武士刀，4次。X4匕首7次 | O12: F | P12: =RANK(Y12,Y:Y) -> 20 | Q12: =RANK(Z12,Z:Z) -> 11 | R12: =RANK(AA12,AA:AA) -> 17 | S12: =RANK(AB12,AB:AB) -> 7 | T12: =RANK(AC12,AC:AC) -> 5 | U12: =Y12+Z12+AA12+AB12+AC12 -> 1020 | W12: =C12 -> 29 | Y12: =IFERROR(VALUE(LEFT(AE12,FIND("(",AE12)-1))+($W12-1)*VALUE(MID(AE12,FIND("+",AE12)+1,FIND(")",AE12)-FIND("+",AE12)-1)),"") -> 178 | Z12: =IFERROR(VALUE(LEFT(AF12,FIND("(",AF12)-1))+($W12-1)*VALUE(MID(AF12,FIND("+",AF12)+1,FIND(")",AF12)-FIND("+",AF12)-1)),"") -> 210 | AA12: =IFERROR(VALUE(LEFT(AG12,FIND("(",AG12)-1))+($W12-1)*VALUE(MID(AG12,FIND("+",AG12)+1,FIND(")",AG12)-FIND("+",AG12)-1)),"") -> 178 | AB12: =IFERROR(VALUE(LEFT(AH12,FIND("(",AH12)-1))+($W12-1)*VALUE(MID(AH12,FIND("+",AH12)+1,FIND(")",AH12)-FIND("+",AH12)-1)),"") -> 210 | AC12: =IFERROR(VALUE(LEFT(AI12,FIND("(",AI12)-1))+($W12-1)*VALUE(MID(AI12,FIND("+",AI12)+1,FIND(")",AI12)-FIND("+",AI12)-1)),"") -> 244 | AE12: =IFERROR(VLOOKUP($A12,全人物技能说明!$A$1:$O$99,9,FALSE),"") -> 38(+5) | AF12: =IFERROR(VLOOKUP($A12,全人物技能说明!$A$1:$O$99,10,FALSE),"") -> 42(+6) | AG12: =IFERROR(VLOOKUP($A12,全人物技能说明!$A$1:$O$99,11,FALSE),"") -> 38(+5) | AH12: =IFERROR(VLOOKUP($A12,全人物技能说明!$A$1:$O$99,12,FALSE),"") -> 42(+6) | AI12: =IFERROR(VLOOKUP($A12,全人物技能说明!$A$1:$O$99,13,FALSE),"") -> 48(+7)
A13: MARTINA | B13: =IFERROR(VLOOKUP($A13,全人物技能说明!$A$1:$O$99,2,FALSE),"") -> 玛蒂娜 | C13: 28 | D13: =IFERROR(VLOOKUP($A13,全人物技能说明!$A$1:$O$99,3,FALSE),"") -> 1剧情 | E13: =IFERROR(VLOOKUP($A13,全人物技能说明!$A$1:$O$99,4,FALSE),"") -> 普通 | F13: =IFERROR(VLOOKUP($A13,全人物技能说明!$A$1:$O$99,7,FALSE),"") -> 0 | G13: =IFERROR(VLOOKUP($A13,全人物技能说明!$A$1:$O$99,8,FALSE),"") -> 跳向最虚弱的敌人，造成 [200% DPS] 伤害。 | H13: 跳跃到最弱的敌人身上，造成 [150?% DPS] 伤害。 | I13: =IFERROR(VLOOKUP($A13,全人物技能说明!$A$1:$O$99,14,FALSE),"") -> W, I | J13: =IFERROR(VLOOKUP($A13,全人物技能说明!$A$1:$O$99,15,FALSE),"") -> A | K13: W | L13: W | M13: =IFERROR(IF(VLOOKUP($A13,全人物技能说明!$A$1:$O$99,7,FALSE)<>"",VLOOKUP($A13,全人物技能说明!$A$1:$O$99,7,FALSE),""),"") | O13: 广播 | P13: =RANK(Y13,Y:Y) -> 5 | Q13: =RANK(Z13,Z:Z) -> 24 | R13: =RANK(AA13,AA:AA) -> 5 | S13: =RANK(AB13,AB:AB) -> 19 | T13: =RANK(AC13,AC:AC) -> 12 | U13: =Y13+Z13+AA13+AB13+AC13 -> 991 | W13: =C13 -> 28 | Y13: =IFERROR(VALUE(LEFT(AE13,FIND("(",AE13)-1))+($W13-1)*VALUE(MID(AE13,FIND("+",AE13)+1,FIND(")",AE13)-FIND("+",AE13)-1)),"") -> 237 | Z13: =IFERROR(VALUE(LEFT(AF13,FIND("(",AF13)-1))+($W13-1)*VALUE(MID(AF13,FIND("+",AF13)+1,FIND(")",AF13)-FIND("+",AF13)-1)),"") -> 140 | AA13: =IFERROR(VALUE(LEFT(AG13,FIND("(",AG13)-1))+($W13-1)*VALUE(MID(AG13,FIND("+",AG13)+1,FIND(")",AG13)-FIND("+",AG13)-1)),"") -> 237 | AB13: =IFERROR(VALUE(LEFT(AH13,FIND("(",AH13)-1))+($W13-1)*VALUE(MID(AH13,FIND("+",AH13)+1,FIND(")",AH13)-FIND("+",AH13)-1)),"") -> 173 | AC13: =IFERROR(VALUE(LEFT(AI13,FIND("(",AI13)-1))+($W13-1)*VALUE(MID(AI13,FIND("+",AI13)+1,FIND(")",AI13)-FIND("+",AI13)-1)),"") -> 204 | AE13: =IFERROR(VLOOKUP($A13,全人物技能说明!$A$1:$O$99,9,FALSE),"") -> 48(+7) | AF13: =IFERROR(VLOOKUP($A13,全人物技能说明!$A$1:$O$99,10,FALSE),"") -> 32(+4) | AG13: =IFERROR(VLOOKUP($A13,全人物技能说明!$A$1:$O$99,11,FALSE),"") -> 48(+7) | AH13: =IFERROR(VLOOKUP($A13,全人物技能说明!$A$1:$O$99,12,FALSE),"") -> 38(+5) | AI13: =IFERROR(VLOOKUP($A13,全人物技能说明!$A$1:$O$99,13,FALSE),"") -> 42(+6) | AM13: F:5, U:5 | AN13: F:5, U:5 | AO13: U:5, F:4 | AP13: 嘲讽/减伤
A14: LANE | B14: =IFERROR(VLOOKUP($A14,全人物技能说明!$A$1:$O$99,2,FALSE),"") -> 莱恩 | C14: 27 | D14: =IFERROR(VLOOKUP($A14,全人物技能说明!$A$1:$O$99,3,FALSE),"") -> 3剧情 | E14: =IFERROR(VLOOKUP($A14,全人物技能说明!$A$1:$O$99,4,FALSE),"") -> 稀有 | F14: =IFERROR(VLOOKUP($A14,全人物技能说明!$A$1:$O$99,7,FALSE),"") -> 0 | G14: =IFERROR(VLOOKUP($A14,全人物技能说明!$A$1:$O$99,8,FALSE),"") -> 骇入敌人装备，对 4 名敌人造成 [25% INT] 伤害，并在 5 回合内减少其 25% 输出伤害。 | H14: 入侵敌方装备，对2名敌人造成 [25% 智力] 伤害，并减少其 25% 伤害，持续2回合。 | I14: =IFERROR(VLOOKUP($A14,全人物技能说明!$A$1:$O$99,14,FALSE),"") -> W, I | J14: =IFERROR(VLOOKUP($A14,全人物技能说明!$A$1:$O$99,15,FALSE),"") -> F | K14: I | L14: I | M14: =IFERROR(IF(VLOOKUP($A14,全人物技能说明!$A$1:$O$99,7,FALSE)<>"",VLOOKUP($A14,全人物技能说明!$A$1:$O$99,7,FALSE),""),"") | O14: 广播 | P14: =RANK(Y14,Y:Y) -> 7 | Q14: =RANK(Z14,Z:Z) -> 17 | R14: =RANK(AA14,AA:AA) -> 7 | S14: =RANK(AB14,AB:AB) -> 28 | T14: =RANK(AC14,AC:AC) -> 13 | U14: =Y14+Z14+AA14+AB14+AC14 -> 933 | W14: =C14 -> 27 | Y14: =IFERROR(VALUE(LEFT(AE14,FIND("(",AE14)-1))+($W14-1)*VALUE(MID(AE14,FIND("+",AE14)+1,FIND(")",AE14)-FIND("+",AE14)-1)),"") -> 223 | Z14: =IFERROR(VALUE(LEFT(AF14,FIND("(",AF14)-1))+($W14-1)*VALUE(MID(AF14,FIND("+",AF14)+1,FIND(")",AF14)-FIND("+",AF14)-1)),"") -> 163 | AA14: =IFERROR(VALUE(LEFT(AG14,FIND("(",AG14)-1))+($W14-1)*VALUE(MID(AG14,FIND("+",AG14)+1,FIND(")",AG14)-FIND("+",AG14)-1)),"") -> 223 | AB14: =IFERROR(VALUE(LEFT(AH14,FIND("(",AH14)-1))+($W14-1)*VALUE(MID(AH14,FIND("+",AH14)+1,FIND(")",AH14)-FIND("+",AH14)-1)),"") -> 132 | AC14: =IFERROR(VALUE(LEFT(AI14,FIND("(",AI14)-1))+($W14-1)*VALUE(MID(AI14,FIND("+",AI14)+1,FIND(")",AI14)-FIND("+",AI14)-1)),"") -> 192 | AE14: =IFERROR(VLOOKUP($A14,全人物技能说明!$A$1:$O$99,9,FALSE),"") -> 41(+7) | AF14: =IFERROR(VLOOKUP($A14,全人物技能说明!$A$1:$O$99,10,FALSE),"") -> 33(+5) | AG14: =IFERROR(VLOOKUP($A14,全人物技能说明!$A$1:$O$99,11,FALSE),"") -> 41(+7) | AH14: =IFERROR(VLOOKUP($A14,全人物技能说明!$A$1:$O$99,12,FALSE),"") -> 28(+4) | AI14: =IFERROR(VLOOKUP($A14,全人物技能说明!$A$1:$O$99,13,FALSE),"") -> 36(+6) | AL14: 平衡/特殊 (Irma, Foxy, PamOne, PamTwo) | AM14: 爱之弓 (Bow of Love) | AN14: JNT套装 (JNT Set) | AO14: 可爱胸针 (Cute Brooch) | AP14: 均衡成长
A15: KARIN | B15: =IFERROR(VLOOKUP($A15,全人物技能说明!$A$1:$O$99,2,FALSE),"") -> 卡琳 | C15: 24 | D15: =IFERROR(VLOOKUP($A15,全人物技能说明!$A$1:$O$99,3,FALSE),"") -> 1箱子 | E15: =IFERROR(VLOOKUP($A15,全人物技能说明!$A$1:$O$99,4,FALSE),"") -> 稀有 | F15: =IFERROR(VLOOKUP($A15,全人物技能说明!$A$1:$O$99,7,FALSE),"") -> 重管，围绕A因为那条分支上AFU。重管在 A、F和U方面的属性是第二高 | G15: =IFERROR(VLOOKUP($A15,全人物技能说明!$A$1:$O$99,8,FALSE),"") -> 恢复活力，回复 [35% HP] 并在 2 回合内获得 [130% DEF] 防御加成。 | H15: 恢复活力，治疗 [?% HP] 生命值两种防御力增强40%，持续5回合。 | I15: =IFERROR(VLOOKUP($A15,全人物技能说明!$A$1:$O$99,14,FALSE),"") -> W, A | J15: =IFERROR(VLOOKUP($A15,全人物技能说明!$A$1:$O$99,15,FALSE),"") -> I, U | K15: F? | L15: AwF | M15: =IFERROR(IF(VLOOKUP($A15,全人物技能说明!$A$1:$O$99,7,FALSE)<>"",VLOOKUP($A15,全人物技能说明!$A$1:$O$99,7,FALSE),""),"") -> 重管，围绕A因为那条分支上AFU。重管在 A、F和U方面的属性是第二高 | O15: 外WI | P15: =RANK(Y15,Y:Y) -> 4 | Q15: =RANK(Z15,Z:Z) -> 8 | R15: =RANK(AA15,AA:AA) -> 15 | S15: =RANK(AB15,AB:AB) -> 9 | T15: =RANK(AC15,AC:AC) -> 16 | U15: =Y15+Z15+AA15+AB15+AC15 -> 1049 | W15: =C15 -> 24 | X15: 1 | Y15: =IFERROR(VALUE(LEFT(AE15,FIND("(",AE15)-1))+($W15-1)*VALUE(MID(AE15,FIND("+",AE15)+1,FIND(")",AE15)-FIND("+",AE15)-1)),"") -> 238 | Z15: =IFERROR(VALUE(LEFT(AF15,FIND("(",AF15)-1))+($W15-1)*VALUE(MID(AF15,FIND("+",AF15)+1,FIND(")",AF15)-FIND("+",AF15)-1)),"") -> 238 | AA15: =IFERROR(VALUE(LEFT(AG15,FIND("(",AG15)-1))+($W15-1)*VALUE(MID(AG15,FIND("+",AG15)+1,FIND(")",AG15)-FIND("+",AG15)-1)),"") -> 182 | AB15: =IFERROR(VALUE(LEFT(AH15,FIND("(",AH15)-1))+($W15-1)*VALUE(MID(AH15,FIND("+",AH15)+1,FIND(")",AH15)-FIND("+",AH15)-1)),"") -> 209 | AC15: =IFERROR(VALUE(LEFT(AI15,FIND("(",AI15)-1))+($W15-1)*VALUE(MID(AI15,FIND("+",AI15)+1,FIND(")",AI15)-FIND("+",AI15)-1)),"") -> 182 | AE15: =IFERROR(VLOOKUP($A15,全人物技能说明!$A$1:$O$99,9,FALSE),"") -> 54(+8) | AF15: =IFERROR(VLOOKUP($A15,全人物技能说明!$A$1:$O$99,10,FALSE),"") -> 54(+8) | AG15: =IFERROR(VLOOKUP($A15,全人物技能说明!$A$1:$O$99,11,FALSE),"") -> 44(+6) | AH15: =IFERROR(VLOOKUP($A15,全人物技能说明!$A$1:$O$99,12,FALSE),"") -> 48(+7) | AI15: =IFERROR(VLOOKUP($A15,全人物技能说明!$A$1:$O$99,13,FALSE),"") -> 44(+6)
A16: Momoka | B16: =IFERROR(VLOOKUP($A16,全人物技能说明!$A$1:$O$99,2,FALSE),"") -> 桃香 | C16: 24 | D16: =IFERROR(VLOOKUP($A16,全人物技能说明!$A$1:$O$99,3,FALSE),"") -> 2箱子 | E16: =IFERROR(VLOOKUP($A16,全人物技能说明!$A$1:$O$99,4,FALSE),"") -> 传说 | F16: =IFERROR(VLOOKUP($A16,全人物技能说明!$A$1:$O$99,7,FALSE),"") -> 0 | G16: =IFERROR(VLOOKUP($A16,全人物技能说明!$A$1:$O$99,8,FALSE),"") -> 揭发恶徒，指挥 1 名队友立即攻击对方。 | H16: 暴露一个恶棍，命令两个盟友立即攻击他。 | I16: =IFERROR(VLOOKUP($A16,全人物技能说明!$A$1:$O$99,14,FALSE),"") -> F, U | J16: =IFERROR(VLOOKUP($A16,全人物技能说明!$A$1:$O$99,15,FALSE),"") -> W | L16: A | M16: =IFERROR(IF(VLOOKUP($A16,全人物技能说明!$A$1:$O$99,7,FALSE)<>"",VLOOKUP($A16,全人物技能说明!$A$1:$O$99,7,FALSE),""),"") | O16: F | P16: =RANK(Y16,Y:Y) -> 33 | Q16: =RANK(Z16,Z:Z) -> 19 | R16: =RANK(AA16,AA:AA) -> 16 | S16: =RANK(AB16,AB:AB) -> 9 | T16: =RANK(AC16,AC:AC) -> 10 | U16: =Y16+Z16+AA16+AB16+AC16 -> 875 | W16: =C16 -> 24 | Y16: =IFERROR(VALUE(LEFT(AE16,FIND("(",AE16)-1))+($W16-1)*VALUE(MID(AE16,FIND("+",AE16)+1,FIND(")",AE16)-FIND("+",AE16)-1)),"") -> 124 | Z16: =IFERROR(VALUE(LEFT(AF16,FIND("(",AF16)-1))+($W16-1)*VALUE(MID(AF16,FIND("+",AF16)+1,FIND(")",AF16)-FIND("+",AF16)-1)),"") -> 153 | AA16: =IFERROR(VALUE(LEFT(AG16,FIND("(",AG16)-1))+($W16-1)*VALUE(MID(AG16,FIND("+",AG16)+1,FIND(")",AG16)-FIND("+",AG16)-1)),"") -> 180 | AB16: =IFERROR(VALUE(LEFT(AH16,FIND("(",AH16)-1))+($W16-1)*VALUE(MID(AH16,FIND("+",AH16)+1,FIND(")",AH16)-FIND("+",AH16)-1)),"") -> 209 | AC16: =IFERROR(VALUE(LEFT(AI16,FIND("(",AI16)-1))+($W16-1)*VALUE(MID(AI16,FIND("+",AI16)+1,FIND(")",AI16)-FIND("+",AI16)-1)),"") -> 209 | AE16: =IFERROR(VLOOKUP($A16,全人物技能说明!$A$1:$O$99,9,FALSE),"") -> 32(+4) | AF16: =IFERROR(VLOOKUP($A16,全人物技能说明!$A$1:$O$99,10,FALSE),"") -> 38(+5) | AG16: =IFERROR(VLOOKUP($A16,全人物技能说明!$A$1:$O$99,11,FALSE),"") -> 42(+6) | AH16: =IFERROR(VLOOKUP($A16,全人物技能说明!$A$1:$O$99,12,FALSE),"") -> 48(+7) | AI16: =IFERROR(VLOOKUP($A16,全人物技能说明!$A$1:$O$99,13,FALSE),"") -> 48(+7) | AM16: W:3, A:4 | AN16: 全属性:3 | AO16: W:4, F:4
A17: CRAZY | B17: =IFERROR(VLOOKUP($A17,全人物技能说明!$A$1:$O$99,2,FALSE),"") -> 疯狂 | C17: 20 | D17: =IFERROR(VLOOKUP($A17,全人物技能说明!$A$1:$O$99,3,FALSE),"") -> 1箱子 | E17: =IFERROR(VLOOKUP($A17,全人物技能说明!$A$1:$O$99,4,FALSE),"") -> 稀有 | F17: =IFERROR(VLOOKUP($A17,全人物技能说明!$A$1:$O$99,7,FALSE),"") -> 0 | G17: =IFERROR(VLOOKUP($A17,全人物技能说明!$A$1:$O$99,8,FALSE),"") -> 向最多 4 名敌人投掷炸弹，造成 [75% DPS] 伤害。 | H17: 向最多 4 名敌人投掷炸弹，对其造成 [75% DPS] 伤害。 | I17: =IFERROR(VLOOKUP($A17,全人物技能说明!$A$1:$O$99,14,FALSE),"") -> A | J17: =IFERROR(VLOOKUP($A17,全人物技能说明!$A$1:$O$99,15,FALSE),"") -> W, U | K17: A | L17: A | M17: =IFERROR(IF(VLOOKUP($A17,全人物技能说明!$A$1:$O$99,7,FALSE)<>"",VLOOKUP($A17,全人物技能说明!$A$1:$O$99,7,FALSE),""),"") | O17: 矿石 | P17: =RANK(Y17,Y:Y) -> 17 | Q17: =RANK(Z17,Z:Z) -> 3 | R17: =RANK(AA17,AA:AA) -> 8 | S17: =RANK(AB17,AB:AB) -> 11 | T17: =RANK(AC17,AC:AC) -> 15 | U17: =Y17+Z17+AA17+AB17+AC17 -> 1053 | W17: =C17 -> 20 | Y17: =IFERROR(VALUE(LEFT(AE17,FIND("(",AE17)-1))+($W17-1)*VALUE(MID(AE17,FIND("+",AE17)+1,FIND(")",AE17)-FIND("+",AE17)-1)),"") -> 183 | Z17: =IFERROR(VALUE(LEFT(AF17,FIND("(",AF17)-1))+($W17-1)*VALUE(MID(AF17,FIND("+",AF17)+1,FIND(")",AF17)-FIND("+",AF17)-1)),"") -> 275 | AA17: =IFERROR(VALUE(LEFT(AG17,FIND("(",AG17)-1))+($W17-1)*VALUE(MID(AG17,FIND("+",AG17)+1,FIND(")",AG17)-FIND("+",AG17)-1)),"") -> 206 | AB17: =IFERROR(VALUE(LEFT(AH17,FIND("(",AH17)-1))+($W17-1)*VALUE(MID(AH17,FIND("+",AH17)+1,FIND(")",AH17)-FIND("+",AH17)-1)),"") -> 206 | AC17: =IFERROR(VALUE(LEFT(AI17,FIND("(",AI17)-1))+($W17-1)*VALUE(MID(AI17,FIND("+",AI17)+1,FIND(")",AI17)-FIND("+",AI17)-1)),"") -> 183 | AE17: =IFERROR(VLOOKUP($A17,全人物技能说明!$A$1:$O$99,9,FALSE),"") -> 50(+7) | AF17: =IFERROR(VLOOKUP($A17,全人物技能说明!$A$1:$O$99,10,FALSE),"") -> 66(+11) | AG17: =IFERROR(VLOOKUP($A17,全人物技能说明!$A$1:$O$99,11,FALSE),"") -> 54(+8) | AH17: =IFERROR(VLOOKUP($A17,全人物技能说明!$A$1:$O$99,12,FALSE),"") -> 54(+8) | AI17: =IFERROR(VLOOKUP($A17,全人物技能说明!$A$1:$O$99,13,FALSE),"") -> 50(+7) | AL17: 工人类 (YASU, ANGELA, Sakaki) | AM17: 扳手 (Wrench) | AN17: 技工上衣 (Mechanic Top) & 技工裙 (Mechanic Skirt) | AO17: 生日纸杯蛋糕 (Birthday Cupcake) | AP17: 生产效率
A18: TESS | B18: =IFERROR(VLOOKUP($A18,全人物技能说明!$A$1:$O$99,2,FALSE),"") -> 泰丝 | C18: 20 | D18: =IFERROR(VLOOKUP($A18,全人物技能说明!$A$1:$O$99,3,FALSE),"") -> 3剧情 | E18: =IFERROR(VLOOKUP($A18,全人物技能说明!$A$1:$O$99,4,FALSE),"") -> 稀有 | F18: =IFERROR(VLOOKUP($A18,全人物技能说明!$A$1:$O$99,7,FALSE),"") -> Tess嘲讽充能速度最快，用X4要快得多，使用管状武器需要 3 次攻击 | G18: =IFERROR(VLOOKUP($A18,全人物技能说明!$A$1:$O$99,8,FALSE),"") -> 嘲讽敌人 2 回合，减少 60% 所受到的伤害。 | H18: 嘲讽所有敌人1回合，将接下来6次攻击造成伤害减少50%。 | I18: =IFERROR(VLOOKUP($A18,全人物技能说明!$A$1:$O$99,14,FALSE),"") -> A, U | J18: =IFERROR(VLOOKUP($A18,全人物技能说明!$A$1:$O$99,15,FALSE),"") -> W, I | L18: A | M18: =IFERROR(IF(VLOOKUP($A18,全人物技能说明!$A$1:$O$99,7,FALSE)<>"",VLOOKUP($A18,全人物技能说明!$A$1:$O$99,7,FALSE),""),"") -> Tess嘲讽充能速度最快，用X4要快得多，使用管状武器需要 3 次攻击 | P18: =RANK(Y18,Y:Y) -> 22 | Q18: =RANK(Z18,Z:Z) -> 12 | R18: =RANK(AA18,AA:AA) -> 22 | S18: =RANK(AB18,AB:AB) -> 18 | T18: =RANK(AC18,AC:AC) -> 11 | U18: =Y18+Z18+AA18+AB18+AC18 -> 909 | W18: =C18 -> 20 | X18: 1 | Y18: =IFERROR(VALUE(LEFT(AE18,FIND("(",AE18)-1))+($W18-1)*VALUE(MID(AE18,FIND("+",AE18)+1,FIND(")",AE18)-FIND("+",AE18)-1)),"") -> 158 | Z18: =IFERROR(VALUE(LEFT(AF18,FIND("(",AF18)-1))+($W18-1)*VALUE(MID(AF18,FIND("+",AF18)+1,FIND(")",AF18)-FIND("+",AF18)-1)),"") -> 206 | AA18: =IFERROR(VALUE(LEFT(AG18,FIND("(",AG18)-1))+($W18-1)*VALUE(MID(AG18,FIND("+",AG18)+1,FIND(")",AG18)-FIND("+",AG18)-1)),"") -> 158 | AB18: =IFERROR(VALUE(LEFT(AH18,FIND("(",AH18)-1))+($W18-1)*VALUE(MID(AH18,FIND("+",AH18)+1,FIND(")",AH18)-FIND("+",AH18)-1)),"") -> 181 | AC18: =IFERROR(VALUE(LEFT(AI18,FIND("(",AI18)-1))+($W18-1)*VALUE(MID(AI18,FIND("+",AI18)+1,FIND(")",AI18)-FIND("+",AI18)-1)),"") -> 206 | AE18: =IFERROR(VLOOKUP($A18,全人物技能说明!$A$1:$O$99,9,FALSE),"") -> 44(+6) | AF18: =IFERROR(VLOOKUP($A18,全人物技能说明!$A$1:$O$99,10,FALSE),"") -> 54(+8) | AG18: =IFERROR(VLOOKUP($A18,全人物技能说明!$A$1:$O$99,11,FALSE),"") -> 44(+6) | AH18: =IFERROR(VLOOKUP($A18,全人物技能说明!$A$1:$O$99,12,FALSE),"") -> 48(+7) | AI18: =IFERROR(VLOOKUP($A18,全人物技能说明!$A$1:$O$99,13,FALSE),"") -> 54(+8)
A19: SARA | B19: =IFERROR(VLOOKUP($A19,全人物技能说明!$A$1:$O$99,2,FALSE),"") -> 萨拉 | C19: 18 | D19: =IFERROR(VLOOKUP($A19,全人物技能说明!$A$1:$O$99,3,FALSE),"") -> 2剧情 | E19: =IFERROR(VLOOKUP($A19,全人物技能说明!$A$1:$O$99,4,FALSE),"") -> 稀有 | F19: =IFERROR(VLOOKUP($A19,全人物技能说明!$A$1:$O$99,7,FALSE),"") -> 0 | G19: =IFERROR(VLOOKUP($A19,全人物技能说明!$A$1:$O$99,8,FALSE),"") -> 指挥 2 名队友立即攻击一名敌人。 | H19: 命令 2 名盟友立即攻击一名敌人。 | I19: =IFERROR(VLOOKUP($A19,全人物技能说明!$A$1:$O$99,14,FALSE),"") -> I, F | J19: =IFERROR(VLOOKUP($A19,全人物技能说明!$A$1:$O$99,15,FALSE),"") -> A, U | L19: I | M19: =IFERROR(IF(VLOOKUP($A19,全人物技能说明!$A$1:$O$99,7,FALSE)<>"",VLOOKUP($A19,全人物技能说明!$A$1:$O$99,7,FALSE),""),"") | O19: 血瓶 | P19: =RANK(Y19,Y:Y) -> 21 | Q19: =RANK(Z19,Z:Z) -> 23 | R19: =RANK(AA19,AA:AA) -> 13 | S19: =RANK(AB19,AB:AB) -> 16 | T19: =RANK(AC19,AC:AC) -> 21 | U19: =Y19+Z19+AA19+AB19+AC19 -> 839 | W19: =C19 -> 18 | Y19: =IFERROR(VALUE(LEFT(AE19,FIND("(",AE19)-1))+($W19-1)*VALUE(MID(AE19,FIND("+",AE19)+1,FIND(")",AE19)-FIND("+",AE19)-1)),"") -> 167 | Z19: =IFERROR(VALUE(LEFT(AF19,FIND("(",AF19)-1))+($W19-1)*VALUE(MID(AF19,FIND("+",AF19)+1,FIND(")",AF19)-FIND("+",AF19)-1)),"") -> 146 | AA19: =IFERROR(VALUE(LEFT(AG19,FIND("(",AG19)-1))+($W19-1)*VALUE(MID(AG19,FIND("+",AG19)+1,FIND(")",AG19)-FIND("+",AG19)-1)),"") -> 190 | AB19: =IFERROR(VALUE(LEFT(AH19,FIND("(",AH19)-1))+($W19-1)*VALUE(MID(AH19,FIND("+",AH19)+1,FIND(")",AH19)-FIND("+",AH19)-1)),"") -> 190 | AC19: =IFERROR(VALUE(LEFT(AI19,FIND("(",AI19)-1))+($W19-1)*VALUE(MID(AI19,FIND("+",AI19)+1,FIND(")",AI19)-FIND("+",AI19)-1)),"") -> 146 | AE19: =IFERROR(VLOOKUP($A19,全人物技能说明!$A$1:$O$99,9,FALSE),"") -> 48(+7) | AF19: =IFERROR(VLOOKUP($A19,全人物技能说明!$A$1:$O$99,10,FALSE),"") -> 44(+6) | AG19: =IFERROR(VLOOKUP($A19,全人物技能说明!$A$1:$O$99,11,FALSE),"") -> 54(+8) | AH19: =IFERROR(VLOOKUP($A19,全人物技能说明!$A$1:$O$99,12,FALSE),"") -> 54(+8) | AI19: =IFERROR(VLOOKUP($A19,全人物技能说明!$A$1:$O$99,13,FALSE),"") -> 44(+6) | AM19: F:5, U:5 | AN19: F:5, U:5 | AO19: F:5, I:5
A20: KIARA | B20: =IFERROR(VLOOKUP($A20,全人物技能说明!$A$1:$O$99,2,FALSE),"") -> 琪亚拉 | C20: 17 | D20: =IFERROR(VLOOKUP($A20,全人物技能说明!$A$1:$O$99,3,FALSE),"") -> 4箱子 | E20: =IFERROR(VLOOKUP($A20,全人物技能说明!$A$1:$O$99,4,FALSE),"") -> 史诗 | F20: =IFERROR(VLOOKUP($A20,全人物技能说明!$A$1:$O$99,7,FALSE),"") -> 0 | G20: =IFERROR(VLOOKUP($A20,全人物技能说明!$A$1:$O$99,8,FALSE),"") -> 指挥 1 名队友瞬间攻击一名敌人。 | H20: 命令2名盟友立即攻击一名敌人。 | I20: =IFERROR(VLOOKUP($A20,全人物技能说明!$A$1:$O$99,14,FALSE),"") -> W, A, F | J20: =IFERROR(VLOOKUP($A20,全人物技能说明!$A$1:$O$99,15,FALSE),"") -> U | L20: A | M20: =IFERROR(IF(VLOOKUP($A20,全人物技能说明!$A$1:$O$99,7,FALSE)<>"",VLOOKUP($A20,全人物技能说明!$A$1:$O$99,7,FALSE),""),"") | P20: =RANK(Y20,Y:Y) -> 19 | Q20: =RANK(Z20,Z:Z) -> 15 | R20: =RANK(AA20,AA:AA) -> 26 | S20: =RANK(AB20,AB:AB) -> 17 | T20: =RANK(AC20,AC:AC) -> 34 | U20: =Y20+Z20+AA20+AB20+AC20 -> 805 | W20: =C20 -> 17 | Y20: =IFERROR(VALUE(LEFT(AE20,FIND("(",AE20)-1))+($W20-1)*VALUE(MID(AE20,FIND("+",AE20)+1,FIND(")",AE20)-FIND("+",AE20)-1)),"") -> 182 | Z20: =IFERROR(VALUE(LEFT(AF20,FIND("(",AF20)-1))+($W20-1)*VALUE(MID(AF20,FIND("+",AF20)+1,FIND(")",AF20)-FIND("+",AF20)-1)),"") -> 182 | AA20: =IFERROR(VALUE(LEFT(AG20,FIND("(",AG20)-1))+($W20-1)*VALUE(MID(AG20,FIND("+",AG20)+1,FIND(")",AG20)-FIND("+",AG20)-1)),"") -> 141 | AB20: =IFERROR(VALUE(LEFT(AH20,FIND("(",AH20)-1))+($W20-1)*VALUE(MID(AH20,FIND("+",AH20)+1,FIND(")",AH20)-FIND("+",AH20)-1)),"") -> 182 | AC20: =IFERROR(VALUE(LEFT(AI20,FIND("(",AI20)-1))+($W20-1)*VALUE(MID(AI20,FIND("+",AI20)+1,FIND(")",AI20)-FIND("+",AI20)-1)),"") -> 118 | AE20: =IFERROR(VLOOKUP($A20,全人物技能说明!$A$1:$O$99,9,FALSE),"") -> 54(+8) | AF20: =IFERROR(VLOOKUP($A20,全人物技能说明!$A$1:$O$99,10,FALSE),"") -> 54(+8) | AG20: =IFERROR(VLOOKUP($A20,全人物技能说明!$A$1:$O$99,11,FALSE),"") -> 45(+6) | AH20: =IFERROR(VLOOKUP($A20,全人物技能说明!$A$1:$O$99,12,FALSE),"") -> 54(+8) | AI20: =IFERROR(VLOOKUP($A20,全人物技能说明!$A$1:$O$99,13,FALSE),"") -> 38(+5)
A21: SAMANTHA | B21: =IFERROR(VLOOKUP($A21,全人物技能说明!$A$1:$O$99,2,FALSE),"") -> 萨曼莎 | C21: 15 | D21: =IFERROR(VLOOKUP($A21,全人物技能说明!$A$1:$O$99,3,FALSE),"") -> 4箱子 | E21: =IFERROR(VLOOKUP($A21,全人物技能说明!$A$1:$O$99,4,FALSE),"") -> 稀有 | F21: =IFERROR(VLOOKUP($A21,全人物技能说明!$A$1:$O$99,7,FALSE),"") -> 0 | G21: =IFERROR(VLOOKUP($A21,全人物技能说明!$A$1:$O$99,8,FALSE),"") -> 魅惑一名敌人，使其眩晕 2 回合，并使其受到的伤害提升 50%。 | H21: 迷惑一个敌人，使其昏迷1圈，并在接下来的3次攻击中增加15%的伤害。 | I21: =IFERROR(VLOOKUP($A21,全人物技能说明!$A$1:$O$99,14,FALSE),"") -> W | J21: =IFERROR(VLOOKUP($A21,全人物技能说明!$A$1:$O$99,15,FALSE),"") -> U | L21: W | M21: =IFERROR(IF(VLOOKUP($A21,全人物技能说明!$A$1:$O$99,7,FALSE)<>"",VLOOKUP($A21,全人物技能说明!$A$1:$O$99,7,FALSE),""),"") | O21: 广播 | P21: =RANK(Y21,Y:Y) -> 8 | Q21: =RANK(Z21,Z:Z) -> 16 | R21: =RANK(AA21,AA:AA) -> 20 | S21: =RANK(AB21,AB:AB) -> 20 | T21: =RANK(AC21,AC:AC) -> 30 | U21: =Y21+Z21+AA21+AB21+AC21 -> 846 | W21: =C21 -> 15 | Y21: =IFERROR(VALUE(LEFT(AE21,FIND("(",AE21)-1))+($W21-1)*VALUE(MID(AE21,FIND("+",AE21)+1,FIND(")",AE21)-FIND("+",AE21)-1)),"") -> 220 | Z21: =IFERROR(VALUE(LEFT(AF21,FIND("(",AF21)-1))+($W21-1)*VALUE(MID(AF21,FIND("+",AF21)+1,FIND(")",AF21)-FIND("+",AF21)-1)),"") -> 166 | AA21: =IFERROR(VALUE(LEFT(AG21,FIND("(",AG21)-1))+($W21-1)*VALUE(MID(AG21,FIND("+",AG21)+1,FIND(")",AG21)-FIND("+",AG21)-1)),"") -> 166 | AB21: =IFERROR(VALUE(LEFT(AH21,FIND("(",AH21)-1))+($W21-1)*VALUE(MID(AH21,FIND("+",AH21)+1,FIND(")",AH21)-FIND("+",AH21)-1)),"") -> 166 | AC21: =IFERROR(VALUE(LEFT(AI21,FIND("(",AI21)-1))+($W21-1)*VALUE(MID(AI21,FIND("+",AI21)+1,FIND(")",AI21)-FIND("+",AI21)-1)),"") -> 128 | AE21: =IFERROR(VLOOKUP($A21,全人物技能说明!$A$1:$O$99,9,FALSE),"") -> 66(+11) | AF21: =IFERROR(VLOOKUP($A21,全人物技能说明!$A$1:$O$99,10,FALSE),"") -> 54(+8) | AG21: =IFERROR(VLOOKUP($A21,全人物技能说明!$A$1:$O$99,11,FALSE),"") -> 54(+8) | AH21: =IFERROR(VLOOKUP($A21,全人物技能说明!$A$1:$O$99,12,FALSE),"") -> 54(+8) | AI21: =IFERROR(VLOOKUP($A21,全人物技能说明!$A$1:$O$99,13,FALSE),"") -> 44(+6) | AL21: C Rank
A22: Rhode | B22: =IFERROR(VLOOKUP($A22,全人物技能说明!$A$1:$O$99,2,FALSE),"") -> 罗德 | C22: 14 | D22: =IFERROR(VLOOKUP($A22,全人物技能说明!$A$1:$O$99,3,FALSE),"") -> 4剧情 | E22: =IFERROR(VLOOKUP($A22,全人物技能说明!$A$1:$O$99,4,FALSE),"") -> 史诗 | F22: =IFERROR(VLOOKUP($A22,全人物技能说明!$A$1:$O$99,7,FALSE),"") -> 0 | G22: =IFERROR(VLOOKUP($A22,全人物技能说明!$A$1:$O$99,8,FALSE),"") -> 发动 5 连击，每次攻击造成 [75% DPS] 伤害。 | H22: 发动2次连续攻击，每次造成 [75% DPS] 伤害。 | I22: =IFERROR(VLOOKUP($A22,全人物技能说明!$A$1:$O$99,14,FALSE),"") -> W, U | J22: =IFERROR(VLOOKUP($A22,全人物技能说明!$A$1:$O$99,15,FALSE),"") -> A, F | K22: W | L22: W | M22: =IFERROR(IF(VLOOKUP($A22,全人物技能说明!$A$1:$O$99,7,FALSE)<>"",VLOOKUP($A22,全人物技能说明!$A$1:$O$99,7,FALSE),""),"") | P22: =RANK(Y22,Y:Y) -> 22 | Q22: =RANK(Z22,Z:Z) -> 31 | R22: =RANK(AA22,AA:AA) -> 27 | S22: =RANK(AB22,AB:AB) -> 33 | T22: =RANK(AC22,AC:AC) -> 18 | U22: =Y22+Z22+AA22+AB22+AC22 -> 701 | W22: =C22 -> 14 | Y22: =IFERROR(VALUE(LEFT(AE22,FIND("(",AE22)-1))+($W22-1)*VALUE(MID(AE22,FIND("+",AE22)+1,FIND(")",AE22)-FIND("+",AE22)-1)),"") -> 158 | Z22: =IFERROR(VALUE(LEFT(AF22,FIND("(",AF22)-1))+($W22-1)*VALUE(MID(AF22,FIND("+",AF22)+1,FIND(")",AF22)-FIND("+",AF22)-1)),"") -> 123 | AA22: =IFERROR(VALUE(LEFT(AG22,FIND("(",AG22)-1))+($W22-1)*VALUE(MID(AG22,FIND("+",AG22)+1,FIND(")",AG22)-FIND("+",AG22)-1)),"") -> 139 | AB22: =IFERROR(VALUE(LEFT(AH22,FIND("(",AH22)-1))+($W22-1)*VALUE(MID(AH22,FIND("+",AH22)+1,FIND(")",AH22)-FIND("+",AH22)-1)),"") -> 123 | AC22: =IFERROR(VALUE(LEFT(AI22,FIND("(",AI22)-1))+($W22-1)*VALUE(MID(AI22,FIND("+",AI22)+1,FIND(")",AI22)-FIND("+",AI22)-1)),"") -> 158 | AE22: =IFERROR(VLOOKUP($A22,全人物技能说明!$A$1:$O$99,9,FALSE),"") -> 54(+8) | AF22: =IFERROR(VLOOKUP($A22,全人物技能说明!$A$1:$O$99,10,FALSE),"") -> 45(+6) | AG22: =IFERROR(VLOOKUP($A22,全人物技能说明!$A$1:$O$99,11,FALSE),"") -> 48(+7) | AH22: =IFERROR(VLOOKUP($A22,全人物技能说明!$A$1:$O$99,12,FALSE),"") -> 45(+6) | AI22: =IFERROR(VLOOKUP($A22,全人物技能说明!$A$1:$O$99,13,FALSE),"") -> 54(+8) | AM22: B Rank
A23: Foxy | B23: =IFERROR(VLOOKUP($A23,全人物技能说明!$A$1:$O$99,2,FALSE),"") -> 福克希 | C23: 14 | D23: =IFERROR(VLOOKUP($A23,全人物技能说明!$A$1:$O$99,3,FALSE),"") -> 4箱子 | E23: =IFERROR(VLOOKUP($A23,全人物技能说明!$A$1:$O$99,4,FALSE),"") -> 稀有 | F23: =IFERROR(VLOOKUP($A23,全人物技能说明!$A$1:$O$99,7,FALSE),"") -> 0 | G23: =IFERROR(VLOOKUP($A23,全人物技能说明!$A$1:$O$99,8,FALSE),"") -> 为最多 2 名血量最低的队友递出饮品，回复 [20% AGI] 生命值，并在 2 回合内提升其 20% 伤害。 | H23: 向2名生命值最低的盟友治疗 [20% AGI] 生命值并提升其20%伤害，持续2回合。 | I23: =IFERROR(VLOOKUP($A23,全人物技能说明!$A$1:$O$99,14,FALSE),"") -> 全能偏A | J23: =IFERROR(VLOOKUP($A23,全人物技能说明!$A$1:$O$99,15,FALSE),"") -> 0 | K23: A | L23: A | M23: =IFERROR(IF(VLOOKUP($A23,全人物技能说明!$A$1:$O$99,7,FALSE)<>"",VLOOKUP($A23,全人物技能说明!$A$1:$O$99,7,FALSE),""),"") | P23: =RANK(Y23,Y:Y) -> 28 | Q23: =RANK(Z23,Z:Z) -> 25 | R23: =RANK(AA23,AA:AA) -> 27 | S23: =RANK(AB23,AB:AB) -> 25 | T23: =RANK(AC23,AC:AC) -> 25 | U23: =Y23+Z23+AA23+AB23+AC23 -> 695 | W23: =C23 -> 14 | Y23: =IFERROR(VALUE(LEFT(AE23,FIND("(",AE23)-1))+($W23-1)*VALUE(MID(AE23,FIND("+",AE23)+1,FIND(")",AE23)-FIND("+",AE23)-1)),"") -> 139 | Z23: =IFERROR(VALUE(LEFT(AF23,FIND("(",AF23)-1))+($W23-1)*VALUE(MID(AF23,FIND("+",AF23)+1,FIND(")",AF23)-FIND("+",AF23)-1)),"") -> 139 | AA23: =IFERROR(VALUE(LEFT(AG23,FIND("(",AG23)-1))+($W23-1)*VALUE(MID(AG23,FIND("+",AG23)+1,FIND(")",AG23)-FIND("+",AG23)-1)),"") -> 139 | AB23: =IFERROR(VALUE(LEFT(AH23,FIND("(",AH23)-1))+($W23-1)*VALUE(MID(AH23,FIND("+",AH23)+1,FIND(")",AH23)-FIND("+",AH23)-1)),"") -> 139 | AC23: =IFERROR(VALUE(LEFT(AI23,FIND("(",AI23)-1))+($W23-1)*VALUE(MID(AI23,FIND("+",AI23)+1,FIND(")",AI23)-FIND("+",AI23)-1)),"") -> 139 | AE23: =IFERROR(VLOOKUP($A23,全人物技能说明!$A$1:$O$99,9,FALSE),"") -> 48(+7) | AF23: =IFERROR(VLOOKUP($A23,全人物技能说明!$A$1:$O$99,10,FALSE),"") -> 48(+7) | AG23: =IFERROR(VLOOKUP($A23,全人物技能说明!$A$1:$O$99,11,FALSE),"") -> 48(+7) | AH23: =IFERROR(VLOOKUP($A23,全人物技能说明!$A$1:$O$99,12,FALSE),"") -> 48(+7) | AI23: =IFERROR(VLOOKUP($A23,全人物技能说明!$A$1:$O$99,13,FALSE),"") -> 48(+7) | AN23: A Rank
A24: PamTwo | B24: =IFERROR(VLOOKUP($A24,全人物技能说明!$A$1:$O$99,2,FALSE),"") -> 帕姆2 | C24: 14 | D24: =IFERROR(VLOOKUP($A24,全人物技能说明!$A$1:$O$99,3,FALSE),"") -> 6剧情 | E24: =IFERROR(VLOOKUP($A24,全人物技能说明!$A$1:$O$99,4,FALSE),"") -> 史诗 | F24: =IFERROR(VLOOKUP($A24,全人物技能说明!$A$1:$O$99,7,FALSE),"") -> 近战X2武士刀，4次 | G24: =IFERROR(VLOOKUP($A24,全人物技能说明!$A$1:$O$99,8,FALSE),"") -> 发动 2 连击，每次攻击造成 [150% DPS] 伤害。 | H24: 发起一系列3次攻击，每次处理9损坏，忽略所有防御。 | I24: =IFERROR(VLOOKUP($A24,全人物技能说明!$A$1:$O$99,14,FALSE),"") -> 全能I | J24: =IFERROR(VLOOKUP($A24,全人物技能说明!$A$1:$O$99,15,FALSE),"") -> 0 | K24: I | L24: I | M24: =IFERROR(IF(VLOOKUP($A24,全人物技能说明!$A$1:$O$99,7,FALSE)<>"",VLOOKUP($A24,全人物技能说明!$A$1:$O$99,7,FALSE),""),"") -> 近战X2武士刀，4次 | P24: =RANK(Y24,Y:Y) -> 28 | Q24: =RANK(Z24,Z:Z) -> 25 | R24: =RANK(AA24,AA:AA) -> 27 | S24: =RANK(AB24,AB:AB) -> 25 | T24: =RANK(AC24,AC:AC) -> 25 | U24: =Y24+Z24+AA24+AB24+AC24 -> 695 | W24: =C24 -> 14 | Y24: =IFERROR(VALUE(LEFT(AE24,FIND("(",AE24)-1))+($W24-1)*VALUE(MID(AE24,FIND("+",AE24)+1,FIND(")",AE24)-FIND("+",AE24)-1)),"") -> 139 | Z24: =IFERROR(VALUE(LEFT(AF24,FIND("(",AF24)-1))+($W24-1)*VALUE(MID(AF24,FIND("+",AF24)+1,FIND(")",AF24)-FIND("+",AF24)-1)),"") -> 139 | AA24: =IFERROR(VALUE(LEFT(AG24,FIND("(",AG24)-1))+($W24-1)*VALUE(MID(AG24,FIND("+",AG24)+1,FIND(")",AG24)-FIND("+",AG24)-1)),"") -> 139 | AB24: =IFERROR(VALUE(LEFT(AH24,FIND("(",AH24)-1))+($W24-1)*VALUE(MID(AH24,FIND("+",AH24)+1,FIND(")",AH24)-FIND("+",AH24)-1)),"") -> 139 | AC24: =IFERROR(VALUE(LEFT(AI24,FIND("(",AI24)-1))+($W24-1)*VALUE(MID(AI24,FIND("+",AI24)+1,FIND(")",AI24)-FIND("+",AI24)-1)),"") -> 139 | AE24: =IFERROR(VLOOKUP($A24,全人物技能说明!$A$1:$O$99,9,FALSE),"") -> 48(+7) | AF24: =IFERROR(VLOOKUP($A24,全人物技能说明!$A$1:$O$99,10,FALSE),"") -> 48(+7) | AG24: =IFERROR(VLOOKUP($A24,全人物技能说明!$A$1:$O$99,11,FALSE),"") -> 48(+7) | AH24: =IFERROR(VLOOKUP($A24,全人物技能说明!$A$1:$O$99,12,FALSE),"") -> 48(+7) | AI24: =IFERROR(VLOOKUP($A24,全人物技能说明!$A$1:$O$99,13,FALSE),"") -> 48(+7) | AO24: S Rank | AP24: Formula | AQ24: Raw Formula
A25: CLOE | B25: =IFERROR(VLOOKUP($A25,全人物技能说明!$A$1:$O$99,2,FALSE),"") -> 克洛伊 | C25: 13 | D25: =IFERROR(VLOOKUP($A25,全人物技能说明!$A$1:$O$99,3,FALSE),"") -> 1箱子 | E25: =IFERROR(VLOOKUP($A25,全人物技能说明!$A$1:$O$99,4,FALSE),"") -> 史诗 | F25: =IFERROR(VLOOKUP($A25,全人物技能说明!$A$1:$O$99,7,FALSE),"") -> 0 | G25: =IFERROR(VLOOKUP($A25,全人物技能说明!$A$1:$O$99,8,FALSE),"") -> 向 2 名敌人投掷炸药，造成 [75% DPS] 伤害。 | H25: 向3名敌人投掷炸药，对其造成 [75% DPS] 伤害。 | I25: =IFERROR(VLOOKUP($A25,全人物技能说明!$A$1:$O$99,14,FALSE),"") -> I | J25: =IFERROR(VLOOKUP($A25,全人物技能说明!$A$1:$O$99,15,FALSE),"") -> W | K25: I | L25: I | M25: =IFERROR(IF(VLOOKUP($A25,全人物技能说明!$A$1:$O$99,7,FALSE)<>"",VLOOKUP($A25,全人物技能说明!$A$1:$O$99,7,FALSE),""),"") | O25: 金库 | P25: =RANK(Y25,Y:Y) -> 36 | Q25: =RANK(Z25,Z:Z) -> 20 | R25: =RANK(AA25,AA:AA) -> 10 | S25: =RANK(AB25,AB:AB) -> 22 | T25: =RANK(AC25,AC:AC) -> 19 | U25: =Y25+Z25+AA25+AB25+AC25 -> 764 | W25: =C25 -> 13 | Y25: =IFERROR(VALUE(LEFT(AE25,FIND("(",AE25)-1))+($W25-1)*VALUE(MID(AE25,FIND("+",AE25)+1,FIND(")",AE25)-FIND("+",AE25)-1)),"") -> 116 | Z25: =IFERROR(VALUE(LEFT(AF25,FIND("(",AF25)-1))+($W25-1)*VALUE(MID(AF25,FIND("+",AF25)+1,FIND(")",AF25)-FIND("+",AF25)-1)),"") -> 150 | AA25: =IFERROR(VALUE(LEFT(AG25,FIND("(",AG25)-1))+($W25-1)*VALUE(MID(AG25,FIND("+",AG25)+1,FIND(")",AG25)-FIND("+",AG25)-1)),"") -> 198 | AB25: =IFERROR(VALUE(LEFT(AH25,FIND("(",AH25)-1))+($W25-1)*VALUE(MID(AH25,FIND("+",AH25)+1,FIND(")",AH25)-FIND("+",AH25)-1)),"") -> 150 | AC25: =IFERROR(VALUE(LEFT(AI25,FIND("(",AI25)-1))+($W25-1)*VALUE(MID(AI25,FIND("+",AI25)+1,FIND(")",AI25)-FIND("+",AI25)-1)),"") -> 150 | AE25: =IFERROR(VLOOKUP($A25,全人物技能说明!$A$1:$O$99,9,FALSE),"") -> 44(+6) | AF25: =IFERROR(VLOOKUP($A25,全人物技能说明!$A$1:$O$99,10,FALSE),"") -> 54(+8) | AG25: =IFERROR(VLOOKUP($A25,全人物技能说明!$A$1:$O$99,11,FALSE),"") -> 66(+11) | AH25: =IFERROR(VLOOKUP($A25,全人物技能说明!$A$1:$O$99,12,FALSE),"") -> 54(+8) | AI25: =IFERROR(VLOOKUP($A25,全人物技能说明!$A$1:$O$99,13,FALSE),"") -> 54(+8) | AL25: 32 (+4) | AP25: =32+((Champion_Level-1)*4) -> #NAME? | AQ25: 32+((Champion_Level-1)*4)
A26: Gaia | B26: =IFERROR(VLOOKUP($A26,全人物技能说明!$A$1:$O$99,2,FALSE),"") -> 盖亚 | C26: 13 | D26: =IFERROR(VLOOKUP($A26,全人物技能说明!$A$1:$O$99,3,FALSE),"") -> 4箱子 | E26: =IFERROR(VLOOKUP($A26,全人物技能说明!$A$1:$O$99,4,FALSE),"") -> 传说 | F26: =IFERROR(VLOOKUP($A26,全人物技能说明!$A$1:$O$99,7,FALSE),"") -> 0 | G26: =IFERROR(VLOOKUP($A26,全人物技能说明!$A$1:$O$99,8,FALSE),"") -> 立即攻击最虚弱的敌人，造成 [175% DPS] 伤害。 | I26: =IFERROR(VLOOKUP($A26,全人物技能说明!$A$1:$O$99,14,FALSE),"") -> A, F | J26: =IFERROR(VLOOKUP($A26,全人物技能说明!$A$1:$O$99,15,FALSE),"") -> W, I | K26: A | L26: A | M26: =IFERROR(IF(VLOOKUP($A26,全人物技能说明!$A$1:$O$99,7,FALSE)<>"",VLOOKUP($A26,全人物技能说明!$A$1:$O$99,7,FALSE),""),"") | P26: =RANK(Y26,Y:Y) -> 35 | Q26: =RANK(Z26,Z:Z) -> 20 | R26: =RANK(AA26,AA:AA) -> 35 | S26: =RANK(AB26,AB:AB) -> 22 | T26: =RANK(AC26,AC:AC) -> 27 | U26: =Y26+Z26+AA26+AB26+AC26 -> 666 | W26: =C26 -> 13 | Y26: =IFERROR(VALUE(LEFT(AE26,FIND("(",AE26)-1))+($W26-1)*VALUE(MID(AE26,FIND("+",AE26)+1,FIND(")",AE26)-FIND("+",AE26)-1)),"") -> 117 | Z26: =IFERROR(VALUE(LEFT(AF26,FIND("(",AF26)-1))+($W26-1)*VALUE(MID(AF26,FIND("+",AF26)+1,FIND(")",AF26)-FIND("+",AF26)-1)),"") -> 150 | AA26: =IFERROR(VALUE(LEFT(AG26,FIND("(",AG26)-1))+($W26-1)*VALUE(MID(AG26,FIND("+",AG26)+1,FIND(")",AG26)-FIND("+",AG26)-1)),"") -> 117 | AB26: =IFERROR(VALUE(LEFT(AH26,FIND("(",AH26)-1))+($W26-1)*VALUE(MID(AH26,FIND("+",AH26)+1,FIND(")",AH26)-FIND("+",AH26)-1)),"") -> 150 | AC26: =IFERROR(VALUE(LEFT(AI26,FIND("(",AI26)-1))+($W26-1)*VALUE(MID(AI26,FIND("+",AI26)+1,FIND(")",AI26)-FIND("+",AI26)-1)),"") -> 132 | AE26: =IFERROR(VLOOKUP($A26,全人物技能说明!$A$1:$O$99,9,FALSE),"") -> 45(+6) | AF26: =IFERROR(VLOOKUP($A26,全人物技能说明!$A$1:$O$99,10,FALSE),"") -> 54(+8) | AG26: =IFERROR(VLOOKUP($A26,全人物技能说明!$A$1:$O$99,11,FALSE),"") -> 45(+6) | AH26: =IFERROR(VLOOKUP($A26,全人物技能说明!$A$1:$O$99,12,FALSE),"") -> 54(+8) | AI26: =IFERROR(VLOOKUP($A26,全人物技能说明!$A$1:$O$99,13,FALSE),"") -> 48(+7) | AL26: 38 (+5) | AM26: 38 (+5) | AP26: =38+((Champion_Level-1)*5) -> #NAME? | AQ26: 38+((Champion_Level-1)*5)
A27: Amelia | B27: =IFERROR(VLOOKUP($A27,全人物技能说明!$A$1:$O$99,2,FALSE),"") -> 阿米莉亚 | C27: 13 | D27: =IFERROR(VLOOKUP($A27,全人物技能说明!$A$1:$O$99,3,FALSE),"") -> 5剧情 | E27: =IFERROR(VLOOKUP($A27,全人物技能说明!$A$1:$O$99,4,FALSE),"") -> 史诗 | F27: =IFERROR(VLOOKUP($A27,全人物技能说明!$A$1:$O$99,7,FALSE),"") -> 0 | G27: =IFERROR(VLOOKUP($A27,全人物技能说明!$A$1:$O$99,8,FALSE),"") -> 创造一个诱饵分身（继承 [50% HP] 和 [100% DPS] 的防御），嘲讽敌人最多 2 秒。 | H27: 用[50% HP] 和 [100% DPS]创造一个分身诱饵，嘲讽敌人最4人,持续最多4回合。 | I27: =IFERROR(VLOOKUP($A27,全人物技能说明!$A$1:$O$99,14,FALSE),"") -> A, I | J27: =IFERROR(VLOOKUP($A27,全人物技能说明!$A$1:$O$99,15,FALSE),"") -> W | K27: I | L27: I | M27: =IFERROR(IF(VLOOKUP($A27,全人物技能说明!$A$1:$O$99,7,FALSE)<>"",VLOOKUP($A27,全人物技能说明!$A$1:$O$99,7,FALSE),""),"") | P27: =RANK(Y27,Y:Y) -> 38 | Q27: =RANK(Z27,Z:Z) -> 20 | R27: =RANK(AA27,AA:AA) -> 23 | S27: =RANK(AB27,AB:AB) -> 28 | T27: =RANK(AC27,AC:AC) -> 27 | U27: =Y27+Z27+AA27+AB27+AC27 -> 662 | W27: =C27 -> 13 | Y27: =IFERROR(VALUE(LEFT(AE27,FIND("(",AE27)-1))+($W27-1)*VALUE(MID(AE27,FIND("+",AE27)+1,FIND(")",AE27)-FIND("+",AE27)-1)),"") -> 98 | Z27: =IFERROR(VALUE(LEFT(AF27,FIND("(",AF27)-1))+($W27-1)*VALUE(MID(AF27,FIND("+",AF27)+1,FIND(")",AF27)-FIND("+",AF27)-1)),"") -> 150 | AA27: =IFERROR(VALUE(LEFT(AG27,FIND("(",AG27)-1))+($W27-1)*VALUE(MID(AG27,FIND("+",AG27)+1,FIND(")",AG27)-FIND("+",AG27)-1)),"") -> 150 | AB27: =IFERROR(VALUE(LEFT(AH27,FIND("(",AH27)-1))+($W27-1)*VALUE(MID(AH27,FIND("+",AH27)+1,FIND(")",AH27)-FIND("+",AH27)-1)),"") -> 132 | AC27: =IFERROR(VALUE(LEFT(AI27,FIND("(",AI27)-1))+($W27-1)*VALUE(MID(AI27,FIND("+",AI27)+1,FIND(")",AI27)-FIND("+",AI27)-1)),"") -> 132 | AE27: =IFERROR(VLOOKUP($A27,全人物技能说明!$A$1:$O$99,9,FALSE),"") -> 38(+5) | AF27: =IFERROR(VLOOKUP($A27,全人物技能说明!$A$1:$O$99,10,FALSE),"") -> 54(+8) | AG27: =IFERROR(VLOOKUP($A27,全人物技能说明!$A$1:$O$99,11,FALSE),"") -> 54(+8) | AH27: =IFERROR(VLOOKUP($A27,全人物技能说明!$A$1:$O$99,12,FALSE),"") -> 48(+7) | AI27: =IFERROR(VLOOKUP($A27,全人物技能说明!$A$1:$O$99,13,FALSE),"") -> 48(+7) | AN27: 40 (+6) | AP27: =40+((Champion_Level-1)*6) -> #NAME? | AQ27: 40+((Champion_Level-1)*6)
A28: PamOne | B28: =IFERROR(VLOOKUP($A28,全人物技能说明!$A$1:$O$99,2,FALSE),"") -> 帕姆1 | C28: 13 | D28: =IFERROR(VLOOKUP($A28,全人物技能说明!$A$1:$O$99,3,FALSE),"") -> 6剧情 | E28: =IFERROR(VLOOKUP($A28,全人物技能说明!$A$1:$O$99,4,FALSE),"") -> 史诗 | F28: =IFERROR(VLOOKUP($A28,全人物技能说明!$A$1:$O$99,7,FALSE),"") -> 近战X2武士刀，4次 | G28: =IFERROR(VLOOKUP($A28,全人物技能说明!$A$1:$O$99,8,FALSE),"") -> 发动 4 连击，每次攻击造成 [75% DPS] 伤害。 | H28: 发起一系列3次攻击，每次处理9损坏，忽略所有防御。 | I28: =IFERROR(VLOOKUP($A28,全人物技能说明!$A$1:$O$99,14,FALSE),"") -> 全能W | J28: =IFERROR(VLOOKUP($A28,全人物技能说明!$A$1:$O$99,15,FALSE),"") -> 0 | K28: W | L28: W | M28: =IFERROR(IF(VLOOKUP($A28,全人物技能说明!$A$1:$O$99,7,FALSE)<>"",VLOOKUP($A28,全人物技能说明!$A$1:$O$99,7,FALSE),""),"") -> 近战X2武士刀，4次 | P28: =RANK(Y28,Y:Y) -> 30 | Q28: =RANK(Z28,Z:Z) -> 27 | R28: =RANK(AA28,AA:AA) -> 30 | S28: =RANK(AB28,AB:AB) -> 28 | T28: =RANK(AC28,AC:AC) -> 27 | U28: =Y28+Z28+AA28+AB28+AC28 -> 660 | W28: =C28 -> 13 | Y28: =IFERROR(VALUE(LEFT(AE28,FIND("(",AE28)-1))+($W28-1)*VALUE(MID(AE28,FIND("+",AE28)+1,FIND(")",AE28)-FIND("+",AE28)-1)),"") -> 132 | Z28: =IFERROR(VALUE(LEFT(AF28,FIND("(",AF28)-1))+($W28-1)*VALUE(MID(AF28,FIND("+",AF28)+1,FIND(")",AF28)-FIND("+",AF28)-1)),"") -> 132 | AA28: =IFERROR(VALUE(LEFT(AG28,FIND("(",AG28)-1))+($W28-1)*VALUE(MID(AG28,FIND("+",AG28)+1,FIND(")",AG28)-FIND("+",AG28)-1)),"") -> 132 | AB28: =IFERROR(VALUE(LEFT(AH28,FIND("(",AH28)-1))+($W28-1)*VALUE(MID(AH28,FIND("+",AH28)+1,FIND(")",AH28)-FIND("+",AH28)-1)),"") -> 132 | AC28: =IFERROR(VALUE(LEFT(AI28,FIND("(",AI28)-1))+($W28-1)*VALUE(MID(AI28,FIND("+",AI28)+1,FIND(")",AI28)-FIND("+",AI28)-1)),"") -> 132 | AE28: =IFERROR(VLOOKUP($A28,全人物技能说明!$A$1:$O$99,9,FALSE),"") -> 48(+7) | AF28: =IFERROR(VLOOKUP($A28,全人物技能说明!$A$1:$O$99,10,FALSE),"") -> 48(+7) | AG28: =IFERROR(VLOOKUP($A28,全人物技能说明!$A$1:$O$99,11,FALSE),"") -> 48(+7) | AH28: =IFERROR(VLOOKUP($A28,全人物技能说明!$A$1:$O$99,12,FALSE),"") -> 48(+7) | AI28: =IFERROR(VLOOKUP($A28,全人物技能说明!$A$1:$O$99,13,FALSE),"") -> 48(+7) | AL28: 42 (+6) | AP28: =42+((Champion_Level-1)*6) -> #NAME? | AQ28: 42+((Champion_Level-1)*6)
A29: Liza | B29: =IFERROR(VLOOKUP($A29,全人物技能说明!$A$1:$O$99,2,FALSE),"") -> 丽莎 | C29: 13 | D29: =IFERROR(VLOOKUP($A29,全人物技能说明!$A$1:$O$99,3,FALSE),"") -> 7箱子 | E29: =IFERROR(VLOOKUP($A29,全人物技能说明!$A$1:$O$99,4,FALSE),"") -> 稀有 | F29: =IFERROR(VLOOKUP($A29,全人物技能说明!$A$1:$O$99,7,FALSE),"") -> 近战X2武士刀，4次 | G29: =IFERROR(VLOOKUP($A29,全人物技能说明!$A$1:$O$99,8,FALSE),"") -> 发动 4 连击，每次攻击造成 [90% DPS] 伤害。 | I29: =IFERROR(VLOOKUP($A29,全人物技能说明!$A$1:$O$99,14,FALSE),"") -> W | J29: =IFERROR(VLOOKUP($A29,全人物技能说明!$A$1:$O$99,15,FALSE),"") -> A, F | K29: A | L29: A | M29: =IFERROR(IF(VLOOKUP($A29,全人物技能说明!$A$1:$O$99,7,FALSE)<>"",VLOOKUP($A29,全人物技能说明!$A$1:$O$99,7,FALSE),""),"") -> 近战X2武士刀，4次 | P29: =RANK(Y29,Y:Y) -> 30 | Q29: =RANK(Z29,Z:Z) -> 32 | R29: =RANK(AA29,AA:AA) -> 31 | S29: =RANK(AB29,AB:AB) -> 27 | T29: =RANK(AC29,AC:AC) -> 36 | U29: =Y29+Z29+AA29+AB29+AC29 -> 628 | W29: =C29 -> 13 | Y29: =IFERROR(VALUE(LEFT(AE29,FIND("(",AE29)-1))+($W29-1)*VALUE(MID(AE29,FIND("+",AE29)+1,FIND(")",AE29)-FIND("+",AE29)-1)),"") -> 132 | Z29: =IFERROR(VALUE(LEFT(AF29,FIND("(",AF29)-1))+($W29-1)*VALUE(MID(AF29,FIND("+",AF29)+1,FIND(")",AF29)-FIND("+",AF29)-1)),"") -> 122 | AA29: =IFERROR(VALUE(LEFT(AG29,FIND("(",AG29)-1))+($W29-1)*VALUE(MID(AG29,FIND("+",AG29)+1,FIND(")",AG29)-FIND("+",AG29)-1)),"") -> 126 | AB29: =IFERROR(VALUE(LEFT(AH29,FIND("(",AH29)-1))+($W29-1)*VALUE(MID(AH29,FIND("+",AH29)+1,FIND(")",AH29)-FIND("+",AH29)-1)),"") -> 134 | AC29: =IFERROR(VALUE(LEFT(AI29,FIND("(",AI29)-1))+($W29-1)*VALUE(MID(AI29,FIND("+",AI29)+1,FIND(")",AI29)-FIND("+",AI29)-1)),"") -> 114 | AE29: =IFERROR(VLOOKUP($A29,全人物技能说明!$A$1:$O$99,9,FALSE),"") -> 48(+7) | AF29: =IFERROR(VLOOKUP($A29,全人物技能说明!$A$1:$O$99,10,FALSE),"") -> 38(+7) | AG29: =IFERROR(VLOOKUP($A29,全人物技能说明!$A$1:$O$99,11,FALSE),"") -> 42(+7) | AH29: =IFERROR(VLOOKUP($A29,全人物技能说明!$A$1:$O$99,12,FALSE),"") -> 38(+8) | AI29: =IFERROR(VLOOKUP($A29,全人物技能说明!$A$1:$O$99,13,FALSE),"") -> 42(+6) | AM29: 45 (+6) | AP29: =45+((Champion_Level-1)*6) -> #NAME? | AQ29: 45+((Champion_Level-1)*6)
